Workbook
Name PxUnit: 'Dados de origem'!$C$6
Name AcoesTot: 'Dados de origem'!$C$7
Name AcoesUnit: 'Dados de origem'!$C$8
Name PL: 'Dados de origem'!$C$9
Name RecCons1T: 'Dados de origem'!$C$11
Name RecTr1T: 'Dados de origem'!$C$12
Name EbitdaCons1T: 'Dados de origem'!$C$13
Name Lucro1T: 'Dados de origem'!$C$14
Name Lucro25: 'Dados de origem'!$C$15
Name DivBruta: 'Dados de origem'!$C$17
Name Caixa: 'Dados de origem'!$C$18
Name DivLiq0: 'Dados de origem'!$C$19
Name NSist: 'Dados de origem'!$C$21
Name CapexTot: 'Dados de origem'!$C$22
Name RapLote: 'Dados de origem'!$C$23
Name CapexLote: 'Dados de origem'!$C$24
Name MWinst: 'Dados de origem'!$C$25
Name Units: 'Dados de origem'!$C$28
Name MktCap: 'Dados de origem'!$C$29
Name FirmValue: 'Dados de origem'!$C$30
Name YieldLeilao: 'Dados de origem'!$C$31
Name RecTrAnual: 'Dados de origem'!$C$32
Name AnoBase: 'Inputs'!$C$5
Name NTNB: 'Inputs'!$C$6
Name ERP: 'Inputs'!$C$7
Name KdReal: 'Inputs'!$C$8
Name Infl: 'Inputs'!$C$9
Name DedTr: 'Inputs'!$C$12
Name OMTr: 'Inputs'!$C$13
Name Erosao: 'Inputs'!$C$14
Name AnoIniVenc: 'Inputs'!$C$15
Name AnoFimVenc: 'Inputs'!$C$16
Name CapexMan: 'Inputs'!$C$17
Name EficCapex: 'Inputs'!$C$20
Name YieldRAP: 'Inputs'!$C$21
Name Lag: 'Inputs'!$C$22
Name CapexA: 'Inputs'!$C$23
Name CapexB: 'Inputs'!$C$24
Name CapexC: 'Inputs'!$C$25
Name CapexD: 'Inputs'!$C$26
Name CapexSoma: 'Inputs'!$C$27
Name PrazoNovo: 'Inputs'!$C$28
Name AnoUltLeilao: 'Inputs'!$C$29
Name CapexRec: 'Inputs'!$C$30
Name MWmed: 'Inputs'!$C$33
Name PxMWh: 'Inputs'!$C$34
Name DedGe: 'Inputs'!$C$35
Name OMGe: 'Inputs'!$C$36
Name ComercRec: 'Inputs'!$C$37
Name ComercMg: 'Inputs'!$C$38
Name AnoFimGer: 'Inputs'!$C$39
Name Holding: 'Inputs'!$C$42
Name TaxEff: 'Inputs'!$C$43
Name Minor: 'Inputs'!$C$44
Name PctDivida: 'Inputs'!$C$45
Name PrazoDiv: 'Inputs'!$C$46
Name VT: 'Inputs'!$C$47
Name Ke: 'Inputs'!$C$49
Name Equity: 'Valuation'!$B$66
Name Alvo: 'Valuation'!$B$68

Sheet Read me
A1: Alupar (ALUP11) — modelo de valuation
A3: O que este arquivo é
A5: Um DCF do fluxo de caixa ao acionista da Alupar, montado em termos REAIS (moeda de hoje). A escolha não é estética: a RAP da transmissão é corrigida por IPCA, então projetar em real e descontar a uma taxa real evita embutir inflação duas vezes — e deixa a TIR resultante diretamente comparável com a NTN-B.
A6: O workbook inteiro é dirigido por fórmulas. Mexer numa célula amarela de Inputs recalcula tudo, inclusive as sensibilidades. Não existe número calculado gravado como valor.
A7: Código de cores
A9: AZUL sobre amarelo, na aba Inputs — premissa editável, é sua para calibrar. AZUL na aba Dados de origem — número público coletado, com a fonte ao lado. PRETO — fórmula. Não digite por cima.
A10: Como o modelo é construído
A12: 1. TRANSMISSÃO. A RAP bruta da base operacional é reconstruída a partir da receita líquida regulatória de transmissão do 1T26 anualizada, revertida pela alíquota de deduções. O pipeline é tratado em bloco: o capex de R$ 9,1 bi é distribuído entre 2026 e 2029, e cada real desembolsado passa a gerar RAP dois anos depois, ao yield do último leilão (RAP/capex do Lote 7 = 8,9%). A base atual expira linearmente entre 2042 e 2055; o pipeline roda 30 anos a partir da energização.
A13: 2. GERAÇÃO. Energia assegurada contratada a preço real constante até o fim das outorgas. É a parte mais frágil do modelo — a companhia não abre o MW médio consolidado nos materiais consultados, então o número é premissa, não dado.
A14: 3. CONSOLIDADO. EBITDA das duas pontas menos holding, imposto efetivo, capex e minoritários. A dívida rola de verdade: capta uma fração do capex de expansão, amortiza linearmente e paga juros reais sobre o saldo. A coluna de alavancagem serve de teste de sanidade — a companhia projeta pico de 3,9–4,0x em 2028, e o modelo deve chegar perto disso com as premissas padrão.
A15: 4. VALUATION. Desconto a meio de ano ao Ke real (NTN-B + prêmio). O preço-alvo sai do equity dividido pelas units equivalentes; a TIR real implícita resolve a taxa que iguala o fluxo ao valor de mercado de hoje.
A16: Onde o modelo é fraco — leia antes de citar qualquer número
... A31: Material de estudo. Não é recomendação de investimento, e os números não foram auditados contra as demonstrações financeiras da companhia. O workbook foi recalculado de ponta a ponta e não contém nenhuma célula de erro, mas isso atesta a aritmética, não as premissas.

Sheet Dados de origem
A1: Dados de origem — números públicos coletados
A2: Azul = coletado de fonte pública, com a fonte na última coluna. Não editar sem trocar a fonte. Tudo que a aba Inputs assume a partir daqui é premissa, não dado.
B4: Item | C4: Valor | D4: Unidade | E4: Fonte
B5: MERCADO
B6: Cotação ALUP11 | C6: 33.75 | D6: R$/unit | E6: Cotação de 15-jul-2026 (agregadores de mercado). Atualize antes de usar.
B7: Total de ações (ON + PN) | C7: 988880601 | D7: ações | E7: Base acionária divulgada em agregadores de mercado, 2026.
B8: Ações por unit (1 ON + 2 PN) | C8: 3 | D8: ações/unit | E8: Composição da unit ALUP11.
B9: Patrimônio líquido | C9: 9290 | D9: R$ mn | E9: Balanço mais recente divulgado (2026).
B10: RESULTADO 1T26 (regulatório)
B11: Receita líquida consolidada 1T26 | C11: 996.8 | D11: R$ mn | E11: Release 1T26: +16,3% a/a.
B12: Receita líquida transmissão 1T26 | C12: 739 | D12: R$ mn | E12: Release 1T26: +16,4% a/a; TCE, reforços ELTE e TBO.
B13: EBITDA regulatório 1T26 | C13: 795 | D13: R$ mn | E13: Release 1T26: +16% a/a, margem 79,7%.
B14: Lucro líquido regulatório 1T26 | C14: 148.9 | D14: R$ mn | E14: Release 1T26: +6,3% a/a.
B15: Lucro líquido regulatório 2025 | C15: 737.6 | D15: R$ mn | E15: Acumulado 2025: +30,7% vs 2024.
B16: DÍVIDA (1T26)
B17: Dívida bruta | C17: 14600 | D17: R$ mn | E17: Release 1T26.
B18: Caixa e aplicações | C18: 5300 | D18: R$ mn | E18: Release 1T26.
B19: Dívida líquida | C19: 9300 | D19: R$ mn | E19: Release 1T26; alavancagem regulatória 3,2x.
B20: ATIVOS E PIPELINE
B21: Sistemas de transmissão em concessão | C21: 44 | D21: un | E21: 31 operacionais e 13 em implantação (operação entre 2026 e 2029).
B22: Capex a investir até 2029 | C22: 9100 | D22: R$ mn | E22: Maior ciclo de investimentos da história da companhia.
B23: RAP do último lote arrematado | C23: 96.72 | D23: R$ mn | E23: Lote 7, Leilão ANEEL 1/2026, 30 anos, energização jun/2031.
B24: Capex do último lote arrematado | C24: 1089 | D24: R$ mn | E24: Mesmo lote — a razão RAP/capex ancora o yield do pipeline.
B25: Capacidade instalada de geração | C25: 798.5 | D25: MW | E25: Hidráulica, eólica e solar no Brasil, Colômbia e Peru.
B27: Derivados diretos
B28: Units equivalentes | C28: =AcoesTot/AcoesUnit | D28: units | E28: Total de ações convertido em units.
B29: Valor de mercado | C29: =Units*PxUnit/1000000 | D29: R$ mn | E29: Units × cotação.
B30: Firm value (mercado + dívida líquida) | C30: =MktCap+DivLiq0 | D30: R$ mn | E30: Referência de entrada do DCF.
B31: Yield de RAP sobre capex (último leilão) | C31: =RapLote/CapexLote | D31: % | E31: Âncora empírica para a RAP do pipeline.
B32: Receita líquida transmissão anualizada | C32: =RecTr1T*4 | D32: R$ mn | E32: 1T26 × 4. Ignora sazonalidade e as entradas de 2026.

Sheet Inputs
A1: Inputs — todo o modelo é dirigido por esta aba
A2: Edite apenas as células AMARELAS. Todas as demais abas recalculam sozinhas. O modelo é integralmente REAL (deflacionado por IPCA), coerente com a indexação da RAP.
B4: DATA-BASE E DESCONTO
B5: Ano-base da avaliação | C5: 2026 | E5: Primeiro ano projetado. O fluxo desse ano é descontado a meio período (t = 0,5).
B6: NTN-B 10 anos (juro real) | C6: 0.07 | E6: Taxa livre de risco real. Como a RAP é indexada ao IPCA, o desconto é real e comparável ao título.
B7: Prêmio de risco de equity (real) | C7: 0.045 | E7: Prêmio exigido sobre a NTN-B. Transmissão é o ativo de menor beta do setor; 4–5 p.p. é a faixa usual.
B8: Custo real da dívida | C8: 0.055 | E8: Custo médio da dívida deflacionado. Alimenta a despesa de juros do fluxo ao acionista.
B9: Inflação de longo prazo (IPCA) | C9: 0.04 | E9: Só converte o resultado real em nominal na aba Valuation. Não afeta preço-alvo nem TIR real.
B11: TRANSMISSÃO — BASE OPERACIONAL
B12: Deduções sobre a RAP | C12: 0.13 | E12: PIS/COFINS, P&D, TFSEE e encargos. Converte RAP bruta em receita líquida — e vice-versa, que é como a RAP base é reconstruída a partir da receita divulgada.
B13: O&M / custos operacionais (% da RAP) | C13: 0.12 | E13: Custo gerencial de operar as linhas. A margem EBITDA implícita é conferida na aba Transmissão.
B14: Erosão real anual da RAP | C14: 0.005 | E14: Captura de forma reduzida as revisões tarifárias periódicas e o degrau de RAP na metade da concessão. Zere para uma RAP real perfeitamente plana.
B15: Início dos vencimentos de concessão | C15: 2042 | E15: Ano em que a RAP da base operacional começa a expirar.
B16: Fim dos vencimentos de concessão | C16: 2055 | E16: Ano em que a última concessão da base atual expira. Entre os dois anos a RAP decai linearmente até zero. É a hipótese mais grosseira do modelo — ver Read me.
B17: Capex de manutenção (% da RAP) | C17: 0.03 | E17: Investimento recorrente para manter os ativos, fora do capex de expansão.
B19: TRANSMISSÃO — PIPELINE
B20: Eficiência de capex vs. referência ANEEL | C20: 0.8 | E20: Quanto a companhia efetivamente gasta para cada real do capex de referência do leilão. Construir abaixo da referência é de onde vem boa parte do retorno em transmissão. 0,80 = constrói 20% abaixo. Em 100% o projeto rende apenas o yield nominal do leilão e a expansão vira destruição de valor.
B21: Yield de RAP sobre o capex novo | C21: =YieldLeilao/EficCapex | E21: RAP por real efetivamente investido. Sai do último leilão (RAP/capex de referência do Lote 7) corrigido pela eficiência acima. Sobrescreva com um número fixo para testar outros leilões.
B22: Defasagem capex → RAP (anos) | C22: 2 | E22: Quantos anos depois do desembolso a RAP começa a ser recebida. Reflete o prazo de construção.
B23: Capex 2026 (% do total) | C23: 0.3 | E23: Distribuição dos R$ 9,1 bi entre 2026 e 2029. A soma dos quatro deve dar 100%.
B24: Capex 2027 (% do total) | C24: 0.3
B25: Capex 2028 (% do total) | C25: 0.25
B26: Capex 2029 (% do total) | C26: 0.15
B27: Soma do cronograma de capex | C27: =CapexA+CapexB+CapexC+CapexD | E27: Confira: precisa ser 100,0%.
B28: Prazo das concessões novas (anos) | C28: 30 | E28: Concessões de 30 anos a partir da energização. Cada safra de capex tem vida própria.
B29: Último ano de novos leilões | C29: 2045 | E29: Até quando a companhia segue arrematando. O horizonte vai a 2080 justamente para que a última safra de capex complete seus 30 anos dentro do modelo — assim o valor terminal é zero de verdade, e não uma perpetuidade escondendo o resultado.
B30: Capex recorrente pós-2029 (R$ mn/ano) | C30: 800 | E30: Quanto a companhia continua investindo em novos leilões depois do ciclo atual. Zerar equivale a supor que a Alupar para de crescer em 2029 e vira uma carteira em run-off — o que derruba o valor e não descreve uma companhia que arremata lote atrás de lote. É a premissa de crescimento do modelo.
B32: GERAÇÃO
B33: Energia assegurada vendida (MW médio) | C33: 430 | E33: Garantia física contratada, bem abaixo dos MW instalados. Premissa — a companhia não abre o número consolidado nos materiais consultados.
B34: Preço real da energia (R$/MWh) | C34: 260 | E34: Preço médio de contratação em termos reais, já considerando renovação de PPAs. Junto com o MW médio, foi calibrado para reproduzir a receita de geração implícita no 1T26 — ver a aferição na aba Consolidado.
B35: Deduções sobre receita de geração | C35: 0.15 | E35: PIS/COFINS e encargos setoriais.
B36: Opex de geração (% da receita líquida) | C36: 0.25 | E36: O&M, seguros e encargos de uso da rede.
B37: Receita de comercialização (R$ mn/ano) | C37: 200 | E37: A Alup, comercializadora do grupo. Entra separada porque gira volume com margem fina — jogá-la dentro da energia assegurada inflaria o MW médio e, com ele, a margem da geração.
B38: Margem EBITDA da comercialização | C38: 0.08 | E38: Margem típica de trading de energia. Baixa por natureza.
B39: Ano final das outorgas de geração | C39: 2045 | E39: Fim médio das outorgas. Depois disso a geração sai do fluxo — renovação vira upside não modelado.
B41: HOLDING, DÍVIDA E IMPOSTOS
B42: Custos de holding (R$ mn/ano, real) | C42: 120 | E42: Estrutura corporativa, fora das SPEs.
B43: Carga tributária efetiva (% do EBITDA) | C43: 0.1 | E43: IR/CSLL de caixa. Muito abaixo dos 34% nominais: as SPEs de transmissão apuram em lucro presumido, em que o imposto sai como ~3–4% da receita bruta, e boa parte do portfólio tem redução de IR por SUDAM/SUDENE. Contra um EBITDA da ordem de R$ 3 bi, isso dá algo entre 5% e 10%. Colocar os 20% que pareciam prudentes derruba o valor em quase 40% e faz cada novo leilão destruir valor — o que não descreve esta companhia.
B44: Minoritários (% do fluxo operacional) | C44: 0.12 | E44: A Alupar consolida SPEs com sócios. Esta fatia do fluxo não pertence ao acionista de ALUP11.
B45: % do capex financiado com dívida | C45: 0.6 | E45: O restante vem do caixa gerado.
...

Sheet Transmissão
A1: Transmissão — RAP real, base operacional e pipeline (R$ mn, moeda de hoje)
A2: A RAP da base operacional é reconstruída a partir da receita líquida divulgada no 1T26; a RAP do pipeline é o capex acumulado (com defasagem) multiplicado pelo yield de leilão.
A4: Ano | B4: Capex expansão | C4: Capex acumulado | D4: Capex de safras vivas | E4: RAP pipeline | F4: RAP base operacional | G4: Fator de vencimento | H4: RAP total | I4: Deduções | J4: Receita líquida | K4: O&M | L4: EBITDA | M4: Margem EBITDA | N4: Capex manutenção
A5: 2026 | B5: =CapexTot*CapexA | C5: =B5 | D5: =SUMPRODUCT(($A$5:$A$59<=A5-Lag)*($A$5:$A$59>A5-Lag-PrazoNovo)*$B$5:$B$59) | E5: =D5*YieldRAP*(1-Erosao)^(A5-AnoBase) | F5: =RecTrAnual/(1-DedTr)*(1-Erosao)^(A5-AnoBase) | G5: =IF(A5<AnoIniVenc,1,MAX(0,1-(A5-AnoIniVenc+1)/(AnoFimVenc-AnoIniVenc+1))) | H5: =F5*G5+E5 | I5: =-H5*DedTr | J5: =H5+I5 | K5: =-H5*OMTr | L5: =J5+K5 | M5: =IFERROR(L5/J5,"") | N5: =-H5*CapexMan
A6: 2027 | B6: =CapexTot*CapexB | C6: =C5+B6 | D6: =SUMPRODUCT(($A$5:$A$59<=A6-Lag)*($A$5:$A$59>A6-Lag-PrazoNovo)*$B$5:$B$59) | E6: =D6*YieldRAP*(1-Erosao)^(A6-AnoBase) | F6: =RecTrAnual/(1-DedTr)*(1-Erosao)^(A6-AnoBase) | G6: =IF(A6<AnoIniVenc,1,MAX(0,1-(A6-AnoIniVenc+1)/(AnoFimVenc-AnoIniVenc+1))) | H6: =F6*G6+E6 | I6: =-H6*DedTr | J6: =H6+I6 | K6: =-H6*OMTr | L6: =J6+K6 | M6: =IFERROR(L6/J6,"") | N6: =-H6*CapexMan
A7: 2028 | B7: =CapexTot*CapexC | C7: =C6+B7 | D7: =SUMPRODUCT(($A$5:$A$59<=A7-Lag)*($A$5:$A$59>A7-Lag-PrazoNovo)*$B$5:$B$59) | E7: =D7*YieldRAP*(1-Erosao)^(A7-AnoBase) | F7: =RecTrAnual/(1-DedTr)*(1-Erosao)^(A7-AnoBase) | G7: =IF(A7<AnoIniVenc,1,MAX(0,1-(A7-AnoIniVenc+1)/(AnoFimVenc-AnoIniVenc+1))) | H7: =F7*G7+E7 | I7: =-H7*DedTr | J7: =H7+I7 | K7: =-H7*OMTr | L7: =J7+K7 | M7: =IFERROR(L7/J7,"") | N7: =-H7*CapexMan
A8: 2029 | B8: =CapexTot*CapexD | C8: =C7+B8 | D8: =SUMPRODUCT(($A$5:$A$59<=A8-Lag)*($A$5:$A$59>A8-Lag-PrazoNovo)*$B$5:$B$59) | E8: =D8*YieldRAP*(1-Erosao)^(A8-AnoBase) | F8: =RecTrAnual/(1-DedTr)*(1-Erosao)^(A8-AnoBase) | G8: =IF(A8<AnoIniVenc,1,MAX(0,1-(A8-AnoIniVenc+1)/(AnoFimVenc-AnoIniVenc+1))) | H8: =F8*G8+E8 | I8: =-H8*DedTr | J8: =H8+I8 | K8: =-H8*OMTr | L8: =J8+K8 | M8: =IFERROR(L8/J8,"") | N8: =-H8*CapexMan
A9: 2030 | B9: =IF(A9<=AnoUltLeilao,CapexRec,0) | C9: =C8+B9 | D9: =SUMPRODUCT(($A$5:$A$59<=A9-Lag)*($A$5:$A$59>A9-Lag-PrazoNovo)*$B$5:$B$59) | E9: =D9*YieldRAP*(1-Erosao)^(A9-AnoBase) | F9: =RecTrAnual/(1-DedTr)*(1-Erosao)^(A9-AnoBase) | G9: =IF(A9<AnoIniVenc,1,MAX(0,1-(A9-AnoIniVenc+1)/(AnoFimVenc-AnoIniVenc+1))) | H9: =F9*G9+E9 | I9: =-H9*DedTr | J9: =H9+I9 | K9: =-H9*OMTr | L9: =J9+K9 | M9: =IFERROR(L9/J9,"") | N9: =-H9*CapexMan
A10: 2031 | B10: =IF(A10<=AnoUltLeilao,CapexRec,0) | C10: =C9+B10 | D10: =SUMPRODUCT(($A$5:$A$59<=A10-Lag)*($A$5:$A$59>A10-Lag-PrazoNovo)*$B$5:$B$59) | E10: =D10*YieldRAP*(1-Erosao)^(A10-AnoBase) | F10: =RecTrAnual/(1-DedTr)*(1-Erosao)^(A10-AnoBase) | G10: =IF(A10<AnoIniVenc,1,MAX(0,1-(A10-AnoIniVenc+1)/(AnoFimVenc-AnoIniVenc+1))) | H10: =F10*G10+E10 | I10: =-H10*DedTr | J10: =H10+I10 | K10: =-H10*OMTr | L10: =J10+K10 | M10: =IFERROR(L10/J10,"") | N10: =-H10*CapexMan
A11: 2032 | B11: =IF(A11<=AnoUltLeilao,CapexRec,0) | C11: =C10+B11 | D11: =SUMPRODUCT(($A$5:$A$59<=A11-Lag)*($A$5:$A$59>A11-Lag-PrazoNovo)*$B$5:$B$59) | E11: =D11*YieldRAP*(1-Erosao)^(A11-AnoBase) | F11: =RecTrAnual/(1-DedTr)*(1-Erosao)^(A11-AnoBase) | G11: =IF(A11<AnoIniVenc,1,MAX(0,1-(A11-AnoIniVenc+1)/(AnoFimVenc-AnoIniVenc+1))) | H11: =F11*G11+E11 | I11: =-H11*DedTr | J11: =H11+I11 | K11: =-H11*OMTr | L11: =J11+K11 | M11: =IFERROR(L11/J11,"") | N11: =-H11*CapexMan
A12: 2033 | B12: =IF(A12<=AnoUltLeilao,CapexRec,0) | C12: =C11+B12 | D12: =SUMPRODUCT(($A$5:$A$59<=A12-Lag)*($A$5:$A$59>A12-Lag-PrazoNovo)*$B$5:$B$59) | E12: =D12*YieldRAP*(1-Erosao)^(A12-AnoBase) | F12: =RecTrAnual/(1-DedTr)*(1-Erosao)^(A12-AnoBase) | G12: =IF(A12<AnoIniVenc,1,MAX(0,1-(A12-AnoIniVenc+1)/(AnoFimVenc-AnoIniVenc+1))) | H12: =F12*G12+E12 | I12: =-H12*DedTr | J12: =H12+I12 | K12: =-H12*OMTr | L12: =J12+K12 | M12: =IFERROR(L12/J12,"") | N12: =-H12*CapexMan
A13: 2034 | B13: =IF(A13<=AnoUltLeilao,CapexRec,0) | C13: =C12+B13 | D13: =SUMPRODUCT(($A$5:$A$59<=A13-Lag)*($A$5:$A$59>A13-Lag-PrazoNovo)*$B$5:$B$59) | E13: =D13*YieldRAP*(1-Erosao)^(A13-AnoBase) | F13: =RecTrAnual/(1-DedTr)*(1-Erosao)^(A13-AnoBase) | G13: =IF(A13<AnoIniVenc,1,MAX(0,1-(A13-AnoIniVenc+1)/(AnoFimVenc-AnoIniVenc+1))) | H13: =F13*G13+E13 | I13: =-H13*DedTr | J13: =H13+I13 | K13: =-H13*OMTr | L13: =J13+K13 | M13: =IFERROR(L13/J13,"") | N13: =-H13*CapexMan
A14: 2035 | B14: =IF(A14<=AnoUltLeilao,CapexRec,0) | C14: =C13+B14 | D14: =SUMPRODUCT(($A$5:$A$59<=A14-Lag)*($A$5:$A$59>A14-Lag-PrazoNovo)*$B$5:$B$59) | E14: =D14*YieldRAP*(1-Erosao)^(A14-AnoBase) | F14: =RecTrAnual/(1-DedTr)*(1-Erosao)^(A14-AnoBase) | G14: =IF(A14<AnoIniVenc,1,MAX(0,1-(A14-AnoIniVenc+1)/(AnoFimVenc-AnoIniVenc+1))) | H14: =F14*G14+E14 | I14: =-H14*DedTr | J14: =H14+I14 | K14: =-H14*OMTr | L14: =J14+K14 | M14: =IFERROR(L14/J14,"") | N14: =-H14*CapexMan
A15: 2036 | B15: =IF(A15<=AnoUltLeilao,CapexRec,0) | C15: =C14+B15 | D15: =SUMPRODUCT(($A$5:$A$59<=A15-Lag)*($A$5:$A$59>A15-Lag-PrazoNovo)*$B$5:$B$59) | E15: =D15*YieldRAP*(1-Erosao)^(A15-AnoBase) | F15: =RecTrAnual/(1-DedTr)*(1-Erosao)^(A15-AnoBase) | G15: =IF(A15<AnoIniVenc,1,MAX(0,1-(A15-AnoIniVenc+1)/(AnoFimVenc-AnoIniVenc+1))) | H15: =F15*G15+E15 | I15: =-H15*DedTr | J15: =H15+I15 | K15: =-H15*OMTr | L15: =J15+K15 | M15: =IFERROR(L15/J15,"") | N15: =-H15*CapexMan
A16: 2037 | B16: =IF(A16<=AnoUltLeilao,CapexRec,0) | C16: =C15+B16 | D16: =SUMPRODUCT(($A$5:$A$59<=A16-Lag)*($A$5:$A$59>A16-Lag-PrazoNovo)*$B$5:$B$59) | E16: =D16*YieldRAP*(1-Erosao)^(A16-AnoBase) | F16: =RecTrAnual/(1-DedTr)*(1-Erosao)^(A16-AnoBase) | G16: =IF(A16<AnoIniVenc,1,MAX(0,1-(A16-AnoIniVenc+1)/(AnoFimVenc-AnoIniVenc+1))) | H16: =F16*G16+E16 | I16: =-H16*DedTr | J16: =H16+I16 | K16: =-H16*OMTr | L16: =J16+K16 | M16: =IFERROR(L16/J16,"") | N16: =-H16*CapexMan
A17: 2038 | B17: =IF(A17<=AnoUltLeilao,CapexRec,0) | C17: =C16+B17 | D17: =SUMPRODUCT(($A$5:$A$59<=A17-Lag)*($A$5:$A$59>A17-Lag-PrazoNovo)*$B$5:$B$59) | E17: =D17*YieldRAP*(1-Erosao)^(A17-AnoBase) | F17: =RecTrAnual/(1-DedTr)*(1-Erosao)^(A17-AnoBase) | G17: =IF(A17<AnoIniVenc,1,MAX(0,1-(A17-AnoIniVenc+1)/(AnoFimVenc-AnoIniVenc+1))) | H17: =F17*G17+E17 | I17: =-H17*DedTr | J17: =H17+I17 | K17: =-H17*OMTr | L17: =J17+K17 | M17: =IFERROR(L17/J17,"") | N17: =-H17*CapexMan
A18: 2039 | B18: =IF(A18<=AnoUltLeilao,CapexRec,0) | C18: =C17+B18 | D18: =SUMPRODUCT(($A$5:$A$59<=A18-Lag)*($A$5:$A$59>A18-Lag-PrazoNovo)*$B$5:$B$59) | E18: =D18*YieldRAP*(1-Erosao)^(A18-AnoBase) | F18: =RecTrAnual/(1-DedTr)*(1-Erosao)^(A18-AnoBase) | G18: =IF(A18<AnoIniVenc,1,MAX(0,1-(A18-AnoIniVenc+1)/(AnoFimVenc-AnoIniVenc+1))) | H18: =F18*G18+E18 | I18: =-H18*DedTr | J18: =H18+I18 | K18: =-H18*OMTr | L18: =J18+K18 | M18: =IFERROR(L18/J18,"") | N18: =-H18*CapexMan
A19: 2040 | B19: =IF(A19<=AnoUltLeilao,CapexRec,0) | C19: =C18+B19 | D19: =SUMPRODUCT(($A$5:$A$59<=A19-Lag)*($A$5:$A$59>A19-Lag-PrazoNovo)*$B$5:$B$59) | E19: =D19*YieldRAP*(1-Erosao)^(A19-AnoBase) | F19: =RecTrAnual/(1-DedTr)*(1-Erosao)^(A19-AnoBase) | G19: =IF(A19<AnoIniVenc,1,MAX(0,1-(A19-AnoIniVenc+1)/(AnoFimVenc-AnoIniVenc+1))) | H19: =F19*G19+E19 | I19: =-H19*DedTr | J19: =H19+I19 | K19: =-H19*OMTr | L19: =J19+K19 | M19: =IFERROR(L19/J19,"") | N19: =-H19*CapexMan
A20: 2041 | B20: =IF(A20<=AnoUltLeilao,CapexRec,0) | C20: =C19+B20 | D20: =SUMPRODUCT(($A$5:$A$59<=A20-Lag)*($A$5:$A$59>A20-Lag-PrazoNovo)*$B$5:$B$59) | E20: =D20*YieldRAP*(1-Erosao)^(A20-AnoBase) | F20: =RecTrAnual/(1-DedTr)*(1-Erosao)^(A20-AnoBase) | G20: =IF(A20<AnoIniVenc,1,MAX(0,1-(A20-AnoIniVenc+1)/(AnoFimVenc-AnoIniVenc+1))) | H20: =F20*G20+E20 | I20: =-H20*DedTr | J20: =H20+I20 | K20: =-H20*OMTr | L20: =J20+K20 | M20: =IFERROR(L20/J20,"") | N20: =-H20*CapexMan
... A59: 2080 | B59: =IF(A59<=AnoUltLeilao,CapexRec,0) | C59: =C58+B59 | D59: =SUMPRODUCT(($A$5:$A$59<=A59-Lag)*($A$5:$A$59>A59-Lag-PrazoNovo)*$B$5:$B$59) | E59: =D59*YieldRAP*(1-Erosao)^(A59-AnoBase) | F59: =RecTrAnual/(1-DedTr)*(1-Erosao)^(A59-AnoBase) | G59: =IF(A59<AnoIniVenc,1,MAX(0,1-(A59-AnoIniVenc+1)/(AnoFimVenc-AnoIniVenc+1))) | H59: =F59*G59+E59 | I59: =-H59*DedTr | J59: =H59+I59 | K59: =-H59*OMTr | L59: =J59+K59 | M59: =IFERROR(L59/J59,"") | N59: =-H59*CapexMan

Sheet Geração
A1: Geração — 798,5 MW instalados, fluxo contratado em termos reais (R$ mn)
A2: Bloco deliberadamente simples: energia assegurada contratada a preço real constante até o fim das outorgas. É a parte do modelo com menos dado público por trás.
A4: Ano | B4: Em outorga | C4: Energia (MW médio) | D4: Receita bruta | E4: Deduções | F4: Receita líquida | G4: Opex | H4: EBITDA geração | I4: Receita de comercialização | J4: EBITDA comercialização | K4: Receita líquida total | L4: EBITDA total
A5: 2026 | B5: =IF(A5<=AnoFimGer,1,0) | C5: =MWmed*B5 | D5: =C5*8760*PxMWh/1000000 | E5: =-D5*DedGe | F5: =D5+E5 | G5: =-F5*OMGe | H5: =F5+G5 | I5: =ComercRec*B5 | J5: =I5*ComercMg | K5: =F5+I5 | L5: =H5+J5
A6: 2027 | B6: =IF(A6<=AnoFimGer,1,0) | C6: =MWmed*B6 | D6: =C6*8760*PxMWh/1000000 | E6: =-D6*DedGe | F6: =D6+E6 | G6: =-F6*OMGe | H6: =F6+G6 | I6: =ComercRec*B6 | J6: =I6*ComercMg | K6: =F6+I6 | L6: =H6+J6
A7: 2028 | B7: =IF(A7<=AnoFimGer,1,0) | C7: =MWmed*B7 | D7: =C7*8760*PxMWh/1000000 | E7: =-D7*DedGe | F7: =D7+E7 | G7: =-F7*OMGe | H7: =F7+G7 | I7: =ComercRec*B7 | J7: =I7*ComercMg | K7: =F7+I7 | L7: =H7+J7
A8: 2029 | B8: =IF(A8<=AnoFimGer,1,0) | C8: =MWmed*B8 | D8: =C8*8760*PxMWh/1000000 | E8: =-D8*DedGe | F8: =D8+E8 | G8: =-F8*OMGe | H8: =F8+G8 | I8: =ComercRec*B8 | J8: =I8*ComercMg | K8: =F8+I8 | L8: =H8+J8
A9: 2030 | B9: =IF(A9<=AnoFimGer,1,0) | C9: =MWmed*B9 | D9: =C9*8760*PxMWh/1000000 | E9: =-D9*DedGe | F9: =D9+E9 | G9: =-F9*OMGe | H9: =F9+G9 | I9: =ComercRec*B9 | J9: =I9*ComercMg | K9: =F9+I9 | L9: =H9+J9
A10: 2031 | B10: =IF(A10<=AnoFimGer,1,0) | C10: =MWmed*B10 | D10: =C10*8760*PxMWh/1000000 | E10: =-D10*DedGe | F10: =D10+E10 | G10: =-F10*OMGe | H10: =F10+G10 | I10: =ComercRec*B10 | J10: =I10*ComercMg | K10: =F10+I10 | L10: =H10+J10
A11: 2032 | B11: =IF(A11<=AnoFimGer,1,0) | C11: =MWmed*B11 | D11: =C11*8760*PxMWh/1000000 | E11: =-D11*DedGe | F11: =D11+E11 | G11: =-F11*OMGe | H11: =F11+G11 | I11: =ComercRec*B11 | J11: =I11*ComercMg | K11: =F11+I11 | L11: =H11+J11
A12: 2033 | B12: =IF(A12<=AnoFimGer,1,0) | C12: =MWmed*B12 | D12: =C12*8760*PxMWh/1000000 | E12: =-D12*DedGe | F12: =D12+E12 | G12: =-F12*OMGe | H12: =F12+G12 | I12: =ComercRec*B12 | J12: =I12*ComercMg | K12: =F12+I12 | L12: =H12+J12
A13: 2034 | B13: =IF(A13<=AnoFimGer,1,0) | C13: =MWmed*B13 | D13: =C13*8760*PxMWh/1000000 | E13: =-D13*DedGe | F13: =D13+E13 | G13: =-F13*OMGe | H13: =F13+G13 | I13: =ComercRec*B13 | J13: =I13*ComercMg | K13: =F13+I13 | L13: =H13+J13
A14: 2035 | B14: =IF(A14<=AnoFimGer,1,0) | C14: =MWmed*B14 | D14: =C14*8760*PxMWh/1000000 | E14: =-D14*DedGe | F14: =D14+E14 | G14: =-F14*OMGe | H14: =F14+G14 | I14: =ComercRec*B14 | J14: =I14*ComercMg | K14: =F14+I14 | L14: =H14+J14
A15: 2036 | B15: =IF(A15<=AnoFimGer,1,0) | C15: =MWmed*B15 | D15: =C15*8760*PxMWh/1000000 | E15: =-D15*DedGe | F15: =D15+E15 | G15: =-F15*OMGe | H15: =F15+G15 | I15: =ComercRec*B15 | J15: =I15*ComercMg | K15: =F15+I15 | L15: =H15+J15
A16: 2037 | B16: =IF(A16<=AnoFimGer,1,0) | C16: =MWmed*B16 | D16: =C16*8760*PxMWh/1000000 | E16: =-D16*DedGe | F16: =D16+E16 | G16: =-F16*OMGe | H16: =F16+G16 | I16: =ComercRec*B16 | J16: =I16*ComercMg | K16: =F16+I16 | L16: =H16+J16
... A59: 2080 | B59: =IF(A59<=AnoFimGer,1,0) | C59: =MWmed*B59 | D59: =C59*8760*PxMWh/1000000 | E59: =-D59*DedGe | F59: =D59+E59 | G59: =-F59*OMGe | H59: =F59+G59 | I59: =ComercRec*B59 | J59: =I59*ComercMg | K59: =F59+I59 | L59: =H59+J59

Sheet Consolidado
A1: Consolidado — fluxo de caixa ao acionista (FCFE) em termos reais (R$ mn)
A2: EBITDA das duas pontas menos holding, impostos, capex, minoritários e serviço da dívida. A dívida rola: capta uma fração do capex de expansão e amortiza linearmente.
A4: Ano | B4: EBITDA transmissão | C4: EBITDA geração + comerc. | D4: Holding | E4: EBITDA consolidado | F4: Impostos efetivos | G4: Capex expansão | H4: Capex manutenção | I4: Minoritários | J4: Fluxo antes da dívida | K4: Dívida — saldo inicial | L4: Captação | M4: Amortização | N4: Juros reais | O4: Dívida — saldo final | P4: Alavancagem (DL/EBITDA) | Q4: FCFE
A5: 2026 | B5: ='Transmissão'!L5 | C5: ='Geração'!L5 | D5: =-Holding | E5: =B5+C5+D5 | F5: =-MAX(0,E5)*TaxEff | G5: =-'Transmissão'!B5 | H5: ='Transmissão'!N5 | I5: =-MAX(0,E5+F5)*Minor | J5: =SUM(E5:I5) | K5: =DivLiq0 | L5: =-G5*PctDivida | M5: =-K5/PrazoDiv | N5: =-K5*KdReal | O5: =K5+L5+M5 | P5: =IFERROR(O5/E5,"") | Q5: =J5+L5+M5+N5
A6: 2027 | B6: ='Transmissão'!L6 | C6: ='Geração'!L6 | D6: =-Holding | E6: =B6+C6+D6 | F6: =-MAX(0,E6)*TaxEff | G6: =-'Transmissão'!B6 | H6: ='Transmissão'!N6 | I6: =-MAX(0,E6+F6)*Minor | J6: =SUM(E6:I6) | K6: =O5 | L6: =-G6*PctDivida | M6: =-K6/PrazoDiv | N6: =-K6*KdReal | O6: =K6+L6+M6 | P6: =IFERROR(O6/E6,"") | Q6: =J6+L6+M6+N6
A7: 2028 | B7: ='Transmissão'!L7 | C7: ='Geração'!L7 | D7: =-Holding | E7: =B7+C7+D7 | F7: =-MAX(0,E7)*TaxEff | G7: =-'Transmissão'!B7 | H7: ='Transmissão'!N7 | I7: =-MAX(0,E7+F7)*Minor | J7: =SUM(E7:I7) | K7: =O6 | L7: =-G7*PctDivida | M7: =-K7/PrazoDiv | N7: =-K7*KdReal | O7: =K7+L7+M7 | P7: =IFERROR(O7/E7,"") | Q7: =J7+L7+M7+N7
A8: 2029 | B8: ='Transmissão'!L8 | C8: ='Geração'!L8 | D8: =-Holding | E8: =B8+C8+D8 | F8: =-MAX(0,E8)*TaxEff | G8: =-'Transmissão'!B8 | H8: ='Transmissão'!N8 | I8: =-MAX(0,E8+F8)*Minor | J8: =SUM(E8:I8) | K8: =O7 | L8: =-G8*PctDivida | M8: =-K8/PrazoDiv | N8: =-K8*KdReal | O8: =K8+L8+M8 | P8: =IFERROR(O8/E8,"") | Q8: =J8+L8+M8+N8
A9: 2030 | B9: ='Transmissão'!L9 | C9: ='Geração'!L9 | D9: =-Holding | E9: =B9+C9+D9 | F9: =-MAX(0,E9)*TaxEff | G9: =-'Transmissão'!B9 | H9: ='Transmissão'!N9 | I9: =-MAX(0,E9+F9)*Minor | J9: =SUM(E9:I9) | K9: =O8 | L9: =-G9*PctDivida | M9: =-K9/PrazoDiv | N9: =-K9*KdReal | O9: =K9+L9+M9 | P9: =IFERROR(O9/E9,"") | Q9: =J9+L9+M9+N9
A10: 2031 | B10: ='Transmissão'!L10 | C10: ='Geração'!L10 | D10: =-Holding | E10: =B10+C10+D10 | F10: =-MAX(0,E10)*TaxEff | G10: =-'Transmissão'!B10 | H10: ='Transmissão'!N10 | I10: =-MAX(0,E10+F10)*Minor | J10: =SUM(E10:I10) | K10: =O9 | L10: =-G10*PctDivida | M10: =-K10/PrazoDiv | N10: =-K10*KdReal | O10: =K10+L10+M10 | P10: =IFERROR(O10/E10,"") | Q10: =J10+L10+M10+N10
A11: 2032 | B11: ='Transmissão'!L11 | C11: ='Geração'!L11 | D11: =-Holding | E11: =B11+C11+D11 | F11: =-MAX(0,E11)*TaxEff | G11: =-'Transmissão'!B11 | H11: ='Transmissão'!N11 | I11: =-MAX(0,E11+F11)*Minor | J11: =SUM(E11:I11) | K11: =O10 | L11: =-G11*PctDivida | M11: =-K11/PrazoDiv | N11: =-K11*KdReal | O11: =K11+L11+M11 | P11: =IFERROR(O11/E11,"") | Q11: =J11+L11+M11+N11
A12: 2033 | B12: ='Transmissão'!L12 | C12: ='Geração'!L12 | D12: =-Holding | E12: =B12+C12+D12 | F12: =-MAX(0,E12)*TaxEff | G12: =-'Transmissão'!B12 | H12: ='Transmissão'!N12 | I12: =-MAX(0,E12+F12)*Minor | J12: =SUM(E12:I12) | K12: =O11 | L12: =-G12*PctDivida | M12: =-K12/PrazoDiv | N12: =-K12*KdReal | O12: =K12+L12+M12 | P12: =IFERROR(O12/E12,"") | Q12: =J12+L12+M12+N12
A13: 2034 | B13: ='Transmissão'!L13 | C13: ='Geração'!L13 | D13: =-Holding | E13: =B13+C13+D13 | F13: =-MAX(0,E13)*TaxEff | G13: =-'Transmissão'!B13 | H13: ='Transmissão'!N13 | I13: =-MAX(0,E13+F13)*Minor | J13: =SUM(E13:I13) | K13: =O12 | L13: =-G13*PctDivida | M13: =-K13/PrazoDiv | N13: =-K13*KdReal | O13: =K13+L13+M13 | P13: =IFERROR(O13/E13,"") | Q13: =J13+L13+M13+N13
A14: 2035 | B14: ='Transmissão'!L14 | C14: ='Geração'!L14 | D14: =-Holding | E14: =B14+C14+D14 | F14: =-MAX(0,E14)*TaxEff | G14: =-'Transmissão'!B14 | H14: ='Transmissão'!N14 | I14: =-MAX(0,E14+F14)*Minor | J14: =SUM(E14:I14) | K14: =O13 | L14: =-G14*PctDivida | M14: =-K14/PrazoDiv | N14: =-K14*KdReal | O14: =K14+L14+M14 | P14: =IFERROR(O14/E14,"") | Q14: =J14+L14+M14+N14
A15: 2036 | B15: ='Transmissão'!L15 | C15: ='Geração'!L15 | D15: =-Holding | E15: =B15+C15+D15 | F15: =-MAX(0,E15)*TaxEff | G15: =-'Transmissão'!B15 | H15: ='Transmissão'!N15 | I15: =-MAX(0,E15+F15)*Minor | J15: =SUM(E15:I15) | K15: =O14 | L15: =-G15*PctDivida | M15: =-K15/PrazoDiv | N15: =-K15*KdReal | O15: =K15+L15+M15 | P15: =IFERROR(O15/E15,"") | Q15: =J15+L15+M15+N15
A16: 2037 | B16: ='Transmissão'!L16 | C16: ='Geração'!L16 | D16: =-Holding | E16: =B16+C16+D16 | F16: =-MAX(0,E16)*TaxEff | G16: =-'Transmissão'!B16 | H16: ='Transmissão'!N16 | I16: =-MAX(0,E16+F16)*Minor | J16: =SUM(E16:I16) | K16: =O15 | L16: =-G16*PctDivida | M16: =-K16/PrazoDiv | N16: =-K16*KdReal | O16: =K16+L16+M16 | P16: =IFERROR(O16/E16,"") | Q16: =J16+L16+M16+N16
A17: 2038 | B17: ='Transmissão'!L17 | C17: ='Geração'!L17 | D17: =-Holding | E17: =B17+C17+D17 | F17: =-MAX(0,E17)*TaxEff | G17: =-'Transmissão'!B17 | H17: ='Transmissão'!N17 | I17: =-MAX(0,E17+F17)*Minor | J17: =SUM(E17:I17) | K17: =O16 | L17: =-G17*PctDivida | M17: =-K17/PrazoDiv | N17: =-K17*KdReal | O17: =K17+L17+M17 | P17: =IFERROR(O17/E17,"") | Q17: =J17+L17+M17+N17
... A59: 2080 | B59: ='Transmissão'!L59 | C59: ='Geração'!L59 | D59: =-Holding | E59: =B59+C59+D59 | F59: =-MAX(0,E59)*TaxEff | G59: =-'Transmissão'!B59 | H59: ='Transmissão'!N59 | I59: =-MAX(0,E59+F59)*Minor | J59: =SUM(E59:I59) | K59: =O58 | L59: =-G59*PctDivida | M59: =-K59/PrazoDiv | N59: =-K59*KdReal | O59: =K59+L59+M59 | P59: =IFERROR(O59/E59,"") | Q59: =J59+L59+M59+N59
A62: AFERIÇÃO CONTRA O DIVULGADO — se estas linhas destoarem, recalibre os Inputs antes de ler o valuation
A63: EBITDA consolidado 2026 do modelo | B63: =E5
A64: EBITDA regulatório 1T26 anualizado | B64: =EbitdaCons1T*4 | D64: Release 1T26 × 4.
A65: Desvio | B65: =IFERROR(B63/B64-1,"") | D65: Tolerável até ~±10%: o run-rate do 1T26 já embute entradas em operação que o modelo distribui ao longo do ano.
A66: Receita de geração + comercialização 2026 | B66: ='Geração'!K5
A67: Receita de geração implícita no 1T26 | B67: =(RecCons1T-RecTr1T)*4 | D67: Receita consolidada menos transmissão, anualizada. Foi contra esta linha que MW médio e preço foram calibrados.
A68: Desvio | B68: =IFERROR(B66/B67-1,"")
A69: Alavancagem máxima até 2035 | B69: =MAX(P5:P14) | D69: A janela para em 2035 de propósito: depois que as concessões começam a expirar o EBITDA cai e o índice dispara sem que isso signifique estresse de crédito — é aritmética de run-off, não alavancagem.
A70: Ano do pico de alavancagem | B70: =INDEX(A5:A14,MATCH(B69,P5:P14,0))
A71: Guidance da companhia | B71: 3.95 | D71: Pico de 3,9–4,0x em 2028, segundo a diretoria de RI. É a melhor aferição disponível do cronograma de capex.

Sheet Valuation
A1: Valuation — DCF do fluxo ao acionista e TIR real implícita
A2: Fluxo real descontado ao Ke real, convenção de meio de ano. A TIR real implícita compara-se diretamente com a NTN-B, porque ambas são taxas reais.
A4: Ano | B4: t (meio de ano) | C4: FCFE real | D4: Fator de desconto | E4: Valor presente | F4: VP acumulado | G4: Fluxo p/ TIR
A5: Hoje | G5: =-MktCap
A6: 2026 | B6: =A6-AnoBase+0.5 | C6: ='Consolidado'!Q5 | D6: =1/(1+Ke)^B6 | E6: =C6*D6 | F6: =E6 | G6: =C6
A7: 2027 | B7: =A7-AnoBase+0.5 | C7: ='Consolidado'!Q6 | D7: =1/(1+Ke)^B7 | E7: =C7*D7 | F7: =F6+E7 | G7: =C7
A8: 2028 | B8: =A8-AnoBase+0.5 | C8: ='Consolidado'!Q7 | D8: =1/(1+Ke)^B8 | E8: =C8*D8 | F8: =F7+E8 | G8: =C8
A9: 2029 | B9: =A9-AnoBase+0.5 | C9: ='Consolidado'!Q8 | D9: =1/(1+Ke)^B9 | E9: =C9*D9 | F9: =F8+E9 | G9: =C9
A10: 2030 | B10: =A10-AnoBase+0.5 | C10: ='Consolidado'!Q9 | D10: =1/(1+Ke)^B10 | E10: =C10*D10 | F10: =F9+E10 | G10: =C10
A11: 2031 | B11: =A11-AnoBase+0.5 | C11: ='Consolidado'!Q10 | D11: =1/(1+Ke)^B11 | E11: =C11*D11 | F11: =F10+E11 | G11: =C11
A12: 2032 | B12: =A12-AnoBase+0.5 | C12: ='Consolidado'!Q11 | D12: =1/(1+Ke)^B12 | E12: =C12*D12 | F12: =F11+E12 | G12: =C12
A13: 2033 | B13: =A13-AnoBase+0.5 | C13: ='Consolidado'!Q12 | D13: =1/(1+Ke)^B13 | E13: =C13*D13 | F13: =F12+E13 | G13: =C13
A14: 2034 | B14: =A14-AnoBase+0.5 | C14: ='Consolidado'!Q13 | D14: =1/(1+Ke)^B14 | E14: =C14*D14 | F14: =F13+E14 | G14: =C14
A15: 2035 | B15: =A15-AnoBase+0.5 | C15: ='Consolidado'!Q14 | D15: =1/(1+Ke)^B15 | E15: =C15*D15 | F15: =F14+E15 | G15: =C15
A16: 2036 | B16: =A16-AnoBase+0.5 | C16: ='Consolidado'!Q15 | D16: =1/(1+Ke)^B16 | E16: =C16*D16 | F16: =F15+E16 | G16: =C16
A17: 2037 | B17: =A17-AnoBase+0.5 | C17: ='Consolidado'!Q16 | D17: =1/(1+Ke)^B17 | E17: =C17*D17 | F17: =F16+E17 | G17: =C17
A18: 2038 | B18: =A18-AnoBase+0.5 | C18: ='Consolidado'!Q17 | D18: =1/(1+Ke)^B18 | E18: =C18*D18 | F18: =F17+E18 | G18: =C18
... A59: 2079 | B59: =A59-AnoBase+0.5 | C59: ='Consolidado'!Q58 | D59: =1/(1+Ke)^B59 | E59: =C59*D59 | F59: =F58+E59 | G59: =C59
A60: 2080 | B60: =A60-AnoBase+0.5 | C60: ='Consolidado'!Q59 | D60: =1/(1+Ke)^B60 | E60: =C60*D60 | F60: =F59+E60 | G60: =C60+VT
A63: RESULTADO
A64: VP do fluxo explícito | B64: =SUM(E6:E60) | C64: R$ mn
A65: VP do valor terminal | B65: =VT/(1+Ke)^B60 | C65: R$ mn
A66: Valor do equity | B66: =B64+B65 | C66: R$ mn
A67: Valor de mercado atual | B67: =MktCap | C67: R$ mn
A68: Preço-alvo por unit | B68: =B66*1000000/Units | C68: R$/unit
A69: Cotação atual | B69: =PxUnit | C69: R$/unit
A70: Upside / (downside) | B70: =B68/B69-1
A71: TIR real implícita (no preço atual) | B71: =IRR(G5:G60,Ke) | C71: a.a. real
A72: TIR nominal equivalente | B72: =(1+B71)*(1+Infl)-1 | C72: a.a.
A73: NTN-B 10 anos | B73: =NTNB | C73: a.a. real
A74: Prêmio sobre a NTN-B | B74: =B71-B73 | C74: p.p.
A75: Gap a explicar (mercado − DCF) | B75: =B67-B66 | C75: R$ mn
A76: Gap por unit | B76: =B75*1000000/Units | C76: R$/unit
A78: ABERTURA POR SEGMENTO (VP do EBITDA após impostos, R$ mn)
A79: Transmissão | B79: =SUMPRODUCT('Consolidado'!B5:B59*(1-TaxEff),D6:D60)
A80: Geração e comercialização | B80: =SUMPRODUCT('Consolidado'!C5:C59*(1-TaxEff),D6:D60)
A81: Holding | B81: =SUMPRODUCT('Consolidado'!D5:D59,D6:D60)
A82: (-) Dívida líquida atual | B82: =-DivLiq0
A83: (-) Minoritários e capex, líquido | B83: =Equity-B79-B80-B81-B82
A84: Valor do equity | B84: =SUM(B79:B83)
...

Sheet Sensibilidade
A1: Sensibilidade
A2: Cada célula reavalia o DCF inteiro pela fórmula — não depende de tabela de dados do Excel, então os números aparecem corretos em qualquer leitor de planilha.
A4: Preço-alvo por unit (R$)
A5: Ke real ↓ / Choque no fluxo → | B5: -0.15 | C5: -0.075 | D5: 0 | E5: 0.075 | F5: 0.15
A6: =Ke+-0.02 | B6: =(SUMPRODUCT('Valuation'!$C$6:$C$60*(1+-0.15),1/(1+$A6)^'Valuation'!$B$6:$B$60)+VT/(1+$A6)^54.5)*1000000/Units | C6: =(SUMPRODUCT('Valuation'!$C$6:$C$60*(1+-0.075),1/(1+$A6)^'Valuation'!$B$6:$B$60)+VT/(1+$A6)^54.5)*1000000/Units | D6: =(SUMPRODUCT('Valuation'!$C$6:$C$60*(1+0.0),1/(1+$A6)^'Valuation'!$B$6:$B$60)+VT/(1+$A6)^54.5)*1000000/Units | E6: =(SUMPRODUCT('Valuation'!$C$6:$C$60*(1+0.075),1/(1+$A6)^'Valuation'!$B$6:$B$60)+VT/(1+$A6)^54.5)*1000000/Units | F6: =(SUMPRODUCT('Valuation'!$C$6:$C$60*(1+0.15),1/(1+$A6)^'Valuation'!$B$6:$B$60)+VT/(1+$A6)^54.5)*1000000/Units
A7: =Ke+-0.01 | B7: =(SUMPRODUCT('Valuation'!$C$6:$C$60*(1+-0.15),1/(1+$A7)^'Valuation'!$B$6:$B$60)+VT/(1+$A7)^54.5)*1000000/Units | C7: =(SUMPRODUCT('Valuation'!$C$6:$C$60*(1+-0.075),1/(1+$A7)^'Valuation'!$B$6:$B$60)+VT/(1+$A7)^54.5)*1000000/Units | D7: =(SUMPRODUCT('Valuation'!$C$6:$C$60*(1+0.0),1/(1+$A7)^'Valuation'!$B$6:$B$60)+VT/(1+$A7)^54.5)*1000000/Units | E7: =(SUMPRODUCT('Valuation'!$C$6:$C$60*(1+0.075),1/(1+$A7)^'Valuation'!$B$6:$B$60)+VT/(1+$A7)^54.5)*1000000/Units | F7: =(SUMPRODUCT('Valuation'!$C$6:$C$60*(1+0.15),1/(1+$A7)^'Valuation'!$B$6:$B$60)+VT/(1+$A7)^54.5)*1000000/Units
A8: =Ke+0.0 | B8: =(SUMPRODUCT('Valuation'!$C$6:$C$60*(1+-0.15),1/(1+$A8)^'Valuation'!$B$6:$B$60)+VT/(1+$A8)^54.5)*1000000/Units | C8: =(SUMPRODUCT('Valuation'!$C$6:$C$60*(1+-0.075),1/(1+$A8)^'Valuation'!$B$6:$B$60)+VT/(1+$A8)^54.5)*1000000/Units | D8: =(SUMPRODUCT('Valuation'!$C$6:$C$60*(1+0.0),1/(1+$A8)^'Valuation'!$B$6:$B$60)+VT/(1+$A8)^54.5)*1000000/Units | E8: =(SUMPRODUCT('Valuation'!$C$6:$C$60*(1+0.075),1/(1+$A8)^'Valuation'!$B$6:$B$60)+VT/(1+$A8)^54.5)*1000000/Units | F8: =(SUMPRODUCT('Valuation'!$C$6:$C$60*(1+0.15),1/(1+$A8)^'Valuation'!$B$6:$B$60)+VT/(1+$A8)^54.5)*1000000/Units
A9: =Ke+0.01 | B9: =(SUMPRODUCT('Valuation'!$C$6:$C$60*(1+-0.15),1/(1+$A9)^'Valuation'!$B$6:$B$60)+VT/(1+$A9)^54.5)*1000000/Units | C9: =(SUMPRODUCT('Valuation'!$C$6:$C$60*(1+-0.075),1/(1+$A9)^'Valuation'!$B$6:$B$60)+VT/(1+$A9)^54.5)*1000000/Units | D9: =(SUMPRODUCT('Valuation'!$C$6:$C$60*(1+0.0),1/(1+$A9)^'Valuation'!$B$6:$B$60)+VT/(1+$A9)^54.5)*1000000/Units | E9: =(SUMPRODUCT('Valuation'!$C$6:$C$60*(1+0.075),1/(1+$A9)^'Valuation'!$B$6:$B$60)+VT/(1+$A9)^54.5)*1000000/Units | F9: =(SUMPRODUCT('Valuation'!$C$6:$C$60*(1+0.15),1/(1+$A9)^'Valuation'!$B$6:$B$60)+VT/(1+$A9)^54.5)*1000000/Units
A10: =Ke+0.02 | B10: =(SUMPRODUCT('Valuation'!$C$6:$C$60*(1+-0.15),1/(1+$A10)^'Valuation'!$B$6:$B$60)+VT/(1+$A10)^54.5)*1000000/Units | C10: =(SUMPRODUCT('Valuation'!$C$6:$C$60*(1+-0.075),1/(1+$A10)^'Valuation'!$B$6:$B$60)+VT/(1+$A10)^54.5)*1000000/Units | D10: =(SUMPRODUCT('Valuation'!$C$6:$C$60*(1+0.0),1/(1+$A10)^'Valuation'!$B$6:$B$60)+VT/(1+$A10)^54.5)*1000000/Units | E10: =(SUMPRODUCT('Valuation'!$C$6:$C$60*(1+0.075),1/(1+$A10)^'Valuation'!$B$6:$B$60)+VT/(1+$A10)^54.5)*1000000/Units | F10: =(SUMPRODUCT('Valuation'!$C$6:$C$60*(1+0.15),1/(1+$A10)^'Valuation'!$B$6:$B$60)+VT/(1+$A10)^54.5)*1000000/Units
A13: Upside vs. cotação atual
A14: Ke real ↓ / Choque no fluxo → | B14: -0.15 | C14: -0.075 | D14: 0 | E14: 0.075 | F14: 0.15
A15: =A6 | B15: =B6/PxUnit-1 | C15: =C6/PxUnit-1 | D15: =D6/PxUnit-1 | E15: =E6/PxUnit-1 | F15: =F6/PxUnit-1
A16: =A7 | B16: =B7/PxUnit-1 | C16: =C7/PxUnit-1 | D16: =D7/PxUnit-1 | E16: =E7/PxUnit-1 | F16: =F7/PxUnit-1
A17: =A8 | B17: =B8/PxUnit-1 | C17: =C8/PxUnit-1 | D17: =D8/PxUnit-1 | E17: =E8/PxUnit-1 | F17: =F8/PxUnit-1
A18: =A9 | B18: =B9/PxUnit-1 | C18: =C9/PxUnit-1 | D18: =D9/PxUnit-1 | E18: =E9/PxUnit-1 | F18: =F9/PxUnit-1
A19: =A10 | B19: =B10/PxUnit-1 | C19: =C10/PxUnit-1 | D19: =D10/PxUnit-1 | E19: =E10/PxUnit-1 | F19: =F10/PxUnit-1
A21: TIR real implícita por preço de entrada
A22: Preço da unit (R$) | B22: =PxUnit*0.8 | C22: =PxUnit*0.9 | D22: =PxUnit*1.0 | E22: =PxUnit*1.1 | F22: =PxUnit*1.2 | G22: =PxUnit*1.3
A23: TIR real implícita | B23: =IRR(B28:B83,Ke) | C23: =IRR(C28:C83,Ke) | D23: =IRR(D28:D83,Ke) | E23: =IRR(E28:E83,Ke) | F23: =IRR(F28:F83,Ke) | G23: =IRR(G28:G83,Ke)
A24: Prêmio sobre a NTN-B | B24: =B23-NTNB | C24: =C23-NTNB | D24: =D23-NTNB | E24: =E23-NTNB | F24: =F23-NTNB | G24: =G23-NTNB
A26: Fluxos usados acima (auxiliar) — ano 0 = desembolso do investidor
A27: Ano | B27: =B22 | C27: =C22 | D27: =D22 | E27: =E22 | F27: =F22 | G27: =G22
A28: Hoje | B28: =-B22*Units/1000000 | C28: =-C22*Units/1000000 | D28: =-D22*Units/1000000 | E28: =-E22*Units/1000000 | F28: =-F22*Units/1000000 | G28: =-G22*Units/1000000
A29: 2026 | B29: ='Valuation'!$G$6 | C29: ='Valuation'!$G$6 | D29: ='Valuation'!$G$6 | E29: ='Valuation'!$G$6 | F29: ='Valuation'!$G$6 | G29: ='Valuation'!$G$6
A30: 2027 | B30: ='Valuation'!$G$7 | C30: ='Valuation'!$G$7 | D30: ='Valuation'!$G$7 | E30: ='Valuation'!$G$7 | F30: ='Valuation'!$G$7 | G30: ='Valuation'!$G$7
A31: 2028 | B31: ='Valuation'!$G$8 | C31: ='Valuation'!$G$8 | D31: ='Valuation'!$G$8 | E31: ='Valuation'!$G$8 | F31: ='Valuation'!$G$8 | G31: ='Valuation'!$G$8
A32: 2029 | B32: ='Valuation'!$G$9 | C32: ='Valuation'!$G$9 | D32: ='Valuation'!$G$9 | E32: ='Valuation'!$G$9 | F32: ='Valuation'!$G$9 | G32: ='Valuation'!$G$9
A33: 2030 | B33: ='Valuation'!$G$10 | C33: ='Valuation'!$G$10 | D33: ='Valuation'!$G$10 | E33: ='Valuation'!$G$10 | F33: ='Valuation'!$G$10 | G33: ='Valuation'!$G$10
A34: 2031 | B34: ='Valuation'!$G$11 | C34: ='Valuation'!$G$11 | D34: ='Valuation'!$G$11 | E34: ='Valuation'!$G$11 | F34: ='Valuation'!$G$11 | G34: ='Valuation'!$G$11
A35: 2032 | B35: ='Valuation'!$G$12 | C35: ='Valuation'!$G$12 | D35: ='Valuation'!$G$12 | E35: ='Valuation'!$G$12 | F35: ='Valuation'!$G$12 | G35: ='Valuation'!$G$12
A36: 2033 | B36: ='Valuation'!$G$13 | C36: ='Valuation'!$G$13 | D36: ='Valuation'!$G$13 | E36: ='Valuation'!$G$13 | F36: ='Valuation'!$G$13 | G36: ='Valuation'!$G$13
A37: 2034 | B37: ='Valuation'!$G$14 | C37: ='Valuation'!$G$14 | D37: ='Valuation'!$G$14 | E37: ='Valuation'!$G$14 | F37: ='Valuation'!$G$14 | G37: ='Valuation'!$G$14
A38: 2035 | B38: ='Valuation'!$G$15 | C38: ='Valuation'!$G$15 | D38: ='Valuation'!$G$15 | E38: ='Valuation'!$G$15 | F38: ='Valuation'!$G$15 | G38: ='Valuation'!$G$15
A39: 2036 | B39: ='Valuation'!$G$16 | C39: ='Valuation'!$G$16 | D39: ='Valuation'!$G$16 | E39: ='Valuation'!$G$16 | F39: ='Valuation'!$G$16 | G39: ='Valuation'!$G$16
A40: 2037 | B40: ='Valuation'!$G$17 | C40: ='Valuation'!$G$17 | D40: ='Valuation'!$G$17 | E40: ='Valuation'!$G$17 | F40: ='Valuation'!$G$17 | G40: ='Valuation'!$G$17
A41: 2038 | B41: ='Valuation'!$G$18 | C41: ='Valuation'!$G$18 | D41: ='Valuation'!$G$18 | E41: ='Valuation'!$G$18 | F41: ='Valuation'!$G$18 | G41: ='Valuation'!$G$18
A42: 2039 | B42: ='Valuation'!$G$19 | C42: ='Valuation'!$G$19 | D42: ='Valuation'!$G$19 | E42: ='Valuation'!$G$19 | F42: ='Valuation'!$G$19 | G42: ='Valuation'!$G$19
A43: 2040 | B43: ='Valuation'!$G$20 | C43: ='Valuation'!$G$20 | D43: ='Valuation'!$G$20 | E43: ='Valuation'!$G$20 | F43: ='Valuation'!$G$20 | G43: ='Valuation'!$G$20
A44: 2041 | B44: ='Valuation'!$G$21 | C44: ='Valuation'!$G$21 | D44: ='Valuation'!$G$21 | E44: ='Valuation'!$G$21 | F44: ='Valuation'!$G$21 | G44: ='Valuation'!$G$21
A45: 2042 | B45: ='Valuation'!$G$22 | C45: ='Valuation'!$G$22 | D45: ='Valuation'!$G$22 | E45: ='Valuation'!$G$22 | F45: ='Valuation'!$G$22 | G45: ='Valuation'!$G$22
...
