Workbook

Sheet Painel
B2: Raio-XP da Bolsa — P/E por Setor
B3: MSCI 12M Forward P/E by Sector | P/L Projetado 12m por Setor
B4: Data de fechamento / Closing date: | C4: 46203
B6: ▶ ATUALIZAR / UPDATE | D6: ← Botão: clique com o Bloomberg conectado. (Atribua a macro AtualizarTudo a este botão/forma.)
B8: Última atualização / Last update: | C8: —
B10: CONFIGURAÇÃO (só na 1ª vez) / ONE-TIME SETUP
B11: 1. Abra o arquivo em um PC com o Terminal Bloomberg (add-in BDH ativo).
B12: Open the file on a PC with the Bloomberg Terminal (BDH add-in enabled).
B13: 2. Alt+F11 → menu Arquivo/File → Import File… → escolha 'mdlRaioXP.bas'.
B14: 3. Clique com o botão direito no botão vermelho acima → Atribuir Macro → AtualizarTudo.
B15: Right-click the red button above → Assign Macro → AtualizarTudo.
B16: 4. Salve como 'Pasta habilitada para macros (*.xlsm)'. / Save as macro-enabled *.xlsm.
B18: USO MENSAL / MONTHLY USE
B19: 1. Ajuste a data de fechamento em C4 (padrão = último mês).
B20: Set the closing date in C4 (default = last month-end).
B21: 2. Clique no botão ATUALIZAR (ou Alt+F8 → AtualizarTudo).
B22: Click the UPDATE button (or Alt+F8 → AtualizarTudo).
... B28: Fonte / Source: Bloomberg — MSCI sector indices (MXBR/MXLA/MXEF/MXWD).

Sheet Consolidated
B2: MSCI – 12M Forward P/E by Sector
C4: Brazil | H4: Latam | M4: EM | R4: World
B5: MSCI Sectors | C5: P/E | D5: 10y Avg. | E5: Min | F5: Max | G5: Range | H5: P/E | I5: 10y Avg. | J5: Min | K5: Max | L5: Range | M5: P/E | N5: 10y Avg. | O5: Min | P5: Max | Q5: Range | R5: P/E | S5: 10y Avg. | T5: Min | U5: Max | V5: Range
B6: Cons. Discretionary | C6: =Data_BR!C130 | D6: =Data_BR!C129 | E6: =Data_BR!C128 | F6: =Data_BR!C127 | H6: =Data_LATAM!C130 | I6: =Data_LATAM!C129 | J6: =Data_LATAM!C128 | K6: =Data_LATAM!C127 | M6: =Data_EM!C130 | N6: =Data_EM!C129 | O6: =Data_EM!C128 | P6: =Data_EM!C127 | R6: =Data_World!C130 | S6: =Data_World!C129 | T6: =Data_World!C128 | U6: =Data_World!C127
B7: Cons. Staples | C7: =Data_BR!D130 | D7: =Data_BR!D129 | E7: =Data_BR!D128 | F7: =Data_BR!D127 | H7: =Data_LATAM!D130 | I7: =Data_LATAM!D129 | J7: =Data_LATAM!D128 | K7: =Data_LATAM!D127 | M7: =Data_EM!D130 | N7: =Data_EM!D129 | O7: =Data_EM!D128 | P7: =Data_EM!D127 | R7: =Data_World!D130 | S7: =Data_World!D129 | T7: =Data_World!D128 | U7: =Data_World!D127
B8: Financials | C8: =Data_BR!E130 | D8: =Data_BR!E129 | E8: =Data_BR!E128 | F8: =Data_BR!E127 | H8: =Data_LATAM!E130 | I8: =Data_LATAM!E129 | J8: =Data_LATAM!E128 | K8: =Data_LATAM!E127 | M8: =Data_EM!E130 | N8: =Data_EM!E129 | O8: =Data_EM!E128 | P8: =Data_EM!E127 | R8: =Data_World!E130 | S8: =Data_World!E129 | T8: =Data_World!E128 | U8: =Data_World!E127
B9: Technology | C9: =Data_BR!F130 | D9: =Data_BR!F129 | E9: =Data_BR!F128 | F9: =Data_BR!F127 | H9: =Data_LATAM!F130 | I9: =Data_LATAM!F129 | J9: =Data_LATAM!F128 | K9: =Data_LATAM!F127 | M9: =Data_EM!F130 | N9: =Data_EM!F129 | O9: =Data_EM!F128 | P9: =Data_EM!F127 | R9: =Data_World!F130 | S9: =Data_World!F129 | T9: =Data_World!F128 | U9: =Data_World!F127
B10: Energy | C10: =Data_BR!G130 | D10: =Data_BR!G129 | E10: =Data_BR!G128 | F10: =Data_BR!G127 | H10: =Data_LATAM!G130 | I10: =Data_LATAM!G129 | J10: =Data_LATAM!G128 | K10: =Data_LATAM!G127 | M10: =Data_EM!G130 | N10: =Data_EM!G129 | O10: =Data_EM!G128 | P10: =Data_EM!G127 | R10: =Data_World!G130 | S10: =Data_World!G129 | T10: =Data_World!G128 | U10: =Data_World!G127
B11: Industrials | C11: =Data_BR!H130 | D11: =Data_BR!H129 | E11: =Data_BR!H128 | F11: =Data_BR!H127 | H11: =Data_LATAM!H130 | I11: =Data_LATAM!H129 | J11: =Data_LATAM!H128 | K11: =Data_LATAM!H127 | M11: =Data_EM!H130 | N11: =Data_EM!H129 | O11: =Data_EM!H128 | P11: =Data_EM!H127 | R11: =Data_World!H130 | S11: =Data_World!H129 | T11: =Data_World!H128 | U11: =Data_World!H127
B12: Materials | C12: =Data_BR!I130 | D12: =Data_BR!I129 | E12: =Data_BR!I128 | F12: =Data_BR!I127 | H12: =Data_LATAM!I130 | I12: =Data_LATAM!I129 | J12: =Data_LATAM!I128 | K12: =Data_LATAM!I127 | M12: =Data_EM!I130 | N12: =Data_EM!I129 | O12: =Data_EM!I128 | P12: =Data_EM!I127 | R12: =Data_World!I130 | S12: =Data_World!I129 | T12: =Data_World!I128 | U12: =Data_World!I127
B13: Utilities | C13: =Data_BR!J130 | D13: =Data_BR!J129 | E13: =Data_BR!J128 | F13: =Data_BR!J127 | H13: =Data_LATAM!J130 | I13: =Data_LATAM!J129 | J13: =Data_LATAM!J128 | K13: =Data_LATAM!J127 | M13: =Data_EM!J130 | N13: =Data_EM!J129 | O13: =Data_EM!J128 | P13: =Data_EM!J127 | R13: =Data_World!J130 | S13: =Data_World!J129 | T13: =Data_World!J128 | U13: =Data_World!J127
B14: Healthcare | C14: =Data_BR!K130 | D14: =Data_BR!K129 | E14: =Data_BR!K128 | F14: =Data_BR!K127 | H14: =Data_LATAM!K130 | I14: =Data_LATAM!K129 | J14: =Data_LATAM!K128 | K14: =Data_LATAM!K127 | M14: =Data_EM!K130 | N14: =Data_EM!K129 | O14: =Data_EM!K128 | P14: =Data_EM!K127 | R14: =Data_World!K130 | S14: =Data_World!K129 | T14: =Data_World!K128 | U14: =Data_World!K127
B15: Telecom | C15: =Data_BR!L130 | D15: =Data_BR!L129 | E15: =Data_BR!L128 | F15: =Data_BR!L127 | H15: =Data_LATAM!L130 | I15: =Data_LATAM!L129 | J15: =Data_LATAM!L128 | K15: =Data_LATAM!L127 | M15: =Data_EM!L130 | N15: =Data_EM!L129 | O15: =Data_EM!L128 | P15: =Data_EM!L127 | R15: =Data_World!L130 | S15: =Data_World!L129 | T15: =Data_World!L128 | U15: =Data_World!L127
B16: Total | C16: =Data_BR!B130 | D16: =Data_BR!B129 | E16: =Data_BR!B128 | F16: =Data_BR!B127 | H16: =Data_LATAM!B130 | I16: =Data_LATAM!B129 | J16: =Data_LATAM!B128 | K16: =Data_LATAM!B127 | M16: =Data_EM!B130 | N16: =Data_EM!B129 | O16: =Data_EM!B128 | P16: =Data_EM!B127 | R16: =Data_World!B130 | S16: =Data_World!B129 | T16: =Data_World!B128 | U16: =Data_World!B127
B18: Source: Bloomberg, XP Research. Date as of | D18: =TEXT(Painel!$C$4,"dd/mm/yyyy")

Sheet Consolidado (PT)
B2: MSCI – P/L Projetado 12m por Setor
C4: Brasil | H4: Latam | M4: Emergentes | R4: Mundo
B5: Setores MSCI | C5: P/L | D5: Média 10a | E5: Mín | F5: Máx | G5: Faixa | H5: P/L | I5: Média 10a | J5: Mín | K5: Máx | L5: Faixa | M5: P/L | N5: Média 10a | O5: Mín | P5: Máx | Q5: Faixa | R5: P/L | S5: Média 10a | T5: Mín | U5: Máx | V5: Faixa
B6: Cons. Discricionário | C6: =Data_BR!C130 | D6: =Data_BR!C129 | E6: =Data_BR!C128 | F6: =Data_BR!C127 | H6: =Data_LATAM!C130 | I6: =Data_LATAM!C129 | J6: =Data_LATAM!C128 | K6: =Data_LATAM!C127 | M6: =Data_EM!C130 | N6: =Data_EM!C129 | O6: =Data_EM!C128 | P6: =Data_EM!C127 | R6: =Data_World!C130 | S6: =Data_World!C129 | T6: =Data_World!C128 | U6: =Data_World!C127
B7: Cons. Básico | C7: =Data_BR!D130 | D7: =Data_BR!D129 | E7: =Data_BR!D128 | F7: =Data_BR!D127 | H7: =Data_LATAM!D130 | I7: =Data_LATAM!D129 | J7: =Data_LATAM!D128 | K7: =Data_LATAM!D127 | M7: =Data_EM!D130 | N7: =Data_EM!D129 | O7: =Data_EM!D128 | P7: =Data_EM!D127 | R7: =Data_World!D130 | S7: =Data_World!D129 | T7: =Data_World!D128 | U7: =Data_World!D127
B8: Financeiro | C8: =Data_BR!E130 | D8: =Data_BR!E129 | E8: =Data_BR!E128 | F8: =Data_BR!E127 | H8: =Data_LATAM!E130 | I8: =Data_LATAM!E129 | J8: =Data_LATAM!E128 | K8: =Data_LATAM!E127 | M8: =Data_EM!E130 | N8: =Data_EM!E129 | O8: =Data_EM!E128 | P8: =Data_EM!E127 | R8: =Data_World!E130 | S8: =Data_World!E129 | T8: =Data_World!E128 | U8: =Data_World!E127
B9: Tecnologia | C9: =Data_BR!F130 | D9: =Data_BR!F129 | E9: =Data_BR!F128 | F9: =Data_BR!F127 | H9: =Data_LATAM!F130 | I9: =Data_LATAM!F129 | J9: =Data_LATAM!F128 | K9: =Data_LATAM!F127 | M9: =Data_EM!F130 | N9: =Data_EM!F129 | O9: =Data_EM!F128 | P9: =Data_EM!F127 | R9: =Data_World!F130 | S9: =Data_World!F129 | T9: =Data_World!F128 | U9: =Data_World!F127
B10: Energia | C10: =Data_BR!G130 | D10: =Data_BR!G129 | E10: =Data_BR!G128 | F10: =Data_BR!G127 | H10: =Data_LATAM!G130 | I10: =Data_LATAM!G129 | J10: =Data_LATAM!G128 | K10: =Data_LATAM!G127 | M10: =Data_EM!G130 | N10: =Data_EM!G129 | O10: =Data_EM!G128 | P10: =Data_EM!G127 | R10: =Data_World!G130 | S10: =Data_World!G129 | T10: =Data_World!G128 | U10: =Data_World!G127
B11: Indústria | C11: =Data_BR!H130 | D11: =Data_BR!H129 | E11: =Data_BR!H128 | F11: =Data_BR!H127 | H11: =Data_LATAM!H130 | I11: =Data_LATAM!H129 | J11: =Data_LATAM!H128 | K11: =Data_LATAM!H127 | M11: =Data_EM!H130 | N11: =Data_EM!H129 | O11: =Data_EM!H128 | P11: =Data_EM!H127 | R11: =Data_World!H130 | S11: =Data_World!H129 | T11: =Data_World!H128 | U11: =Data_World!H127
B12: Materiais | C12: =Data_BR!I130 | D12: =Data_BR!I129 | E12: =Data_BR!I128 | F12: =Data_BR!I127 | H12: =Data_LATAM!I130 | I12: =Data_LATAM!I129 | J12: =Data_LATAM!I128 | K12: =Data_LATAM!I127 | M12: =Data_EM!I130 | N12: =Data_EM!I129 | O12: =Data_EM!I128 | P12: =Data_EM!I127 | R12: =Data_World!I130 | S12: =Data_World!I129 | T12: =Data_World!I128 | U12: =Data_World!I127
B13: Utilities | C13: =Data_BR!J130 | D13: =Data_BR!J129 | E13: =Data_BR!J128 | F13: =Data_BR!J127 | H13: =Data_LATAM!J130 | I13: =Data_LATAM!J129 | J13: =Data_LATAM!J128 | K13: =Data_LATAM!J127 | M13: =Data_EM!J130 | N13: =Data_EM!J129 | O13: =Data_EM!J128 | P13: =Data_EM!J127 | R13: =Data_World!J130 | S13: =Data_World!J129 | T13: =Data_World!J128 | U13: =Data_World!J127
B14: Saúde | C14: =Data_BR!K130 | D14: =Data_BR!K129 | E14: =Data_BR!K128 | F14: =Data_BR!K127 | H14: =Data_LATAM!K130 | I14: =Data_LATAM!K129 | J14: =Data_LATAM!K128 | K14: =Data_LATAM!K127 | M14: =Data_EM!K130 | N14: =Data_EM!K129 | O14: =Data_EM!K128 | P14: =Data_EM!K127 | R14: =Data_World!K130 | S14: =Data_World!K129 | T14: =Data_World!K128 | U14: =Data_World!K127
B15: Telecom | C15: =Data_BR!L130 | D15: =Data_BR!L129 | E15: =Data_BR!L128 | F15: =Data_BR!L127 | H15: =Data_LATAM!L130 | I15: =Data_LATAM!L129 | J15: =Data_LATAM!L128 | K15: =Data_LATAM!L127 | M15: =Data_EM!L130 | N15: =Data_EM!L129 | O15: =Data_EM!L128 | P15: =Data_EM!L127 | R15: =Data_World!L130 | S15: =Data_World!L129 | T15: =Data_World!L128 | U15: =Data_World!L127
B16: Total | C16: =Data_BR!B130 | D16: =Data_BR!B129 | E16: =Data_BR!B128 | F16: =Data_BR!B127 | H16: =Data_LATAM!B130 | I16: =Data_LATAM!B129 | J16: =Data_LATAM!B128 | K16: =Data_LATAM!B127 | M16: =Data_EM!B130 | N16: =Data_EM!B129 | O16: =Data_EM!B128 | P16: =Data_EM!B127 | R16: =Data_World!B130 | S16: =Data_World!B129 | T16: =Data_World!B128 | U16: =Data_World!B127
B18: Fonte: Bloomberg, XP Research. Data-base: | D18: =TEXT(Painel!$C$4,"dd/mm/yyyy")

Sheet Relative
B2: Table 1: Brazil vs Latam – 12M fwd. P/E
B3: Brazil vs. Latam
B4: MSCI Sectors | C4: P/E Brazil | D4: P/E | E4: 10y Avg. | F4: Min | G4: Max | H4: Range
B5: Cons. Discretionary | C5: =Data_BR!C130 | D5: =Calc_Rel!C130 | E5: =Calc_Rel!C129 | F5: =Calc_Rel!C128 | G5: =Calc_Rel!C127
B6: Cons. Staples | C6: =Data_BR!D130 | D6: =Calc_Rel!D130 | E6: =Calc_Rel!D129 | F6: =Calc_Rel!D128 | G6: =Calc_Rel!D127
B7: Financials | C7: =Data_BR!E130 | D7: =Calc_Rel!E130 | E7: =Calc_Rel!E129 | F7: =Calc_Rel!E128 | G7: =Calc_Rel!E127
B8: Technology | C8: =Data_BR!F130 | D8: =Calc_Rel!F130 | E8: =Calc_Rel!F129 | F8: =Calc_Rel!F128 | G8: =Calc_Rel!F127
B9: Energy | C9: =Data_BR!G130 | D9: =Calc_Rel!G130 | E9: =Calc_Rel!G129 | F9: =Calc_Rel!G128 | G9: =Calc_Rel!G127
B10: Industrials | C10: =Data_BR!H130 | D10: =Calc_Rel!H130 | E10: =Calc_Rel!H129 | F10: =Calc_Rel!H128 | G10: =Calc_Rel!H127
B11: Materials | C11: =Data_BR!I130 | D11: =Calc_Rel!I130 | E11: =Calc_Rel!I129 | F11: =Calc_Rel!I128 | G11: =Calc_Rel!I127
B12: Utilities | C12: =Data_BR!J130 | D12: =Calc_Rel!J130 | E12: =Calc_Rel!J129 | F12: =Calc_Rel!J128 | G12: =Calc_Rel!J127
B13: Healthcare | C13: =Data_BR!K130 | D13: =Calc_Rel!K130 | E13: =Calc_Rel!K129 | F13: =Calc_Rel!K128 | G13: =Calc_Rel!K127
B14: Telecom | C14: =Data_BR!L130 | D14: =Calc_Rel!L130 | E14: =Calc_Rel!L129 | F14: =Calc_Rel!L128 | G14: =Calc_Rel!L127
B15: Ibovespa | C15: =Data_BR!B130 | D15: =Calc_Rel!B130 | E15: =Calc_Rel!B129 | F15: =Calc_Rel!B128 | G15: =Calc_Rel!B127
B17: Table 2: Brazil vs EM – 12M fwd. P/E
B18: Brazil vs. EM
B19: MSCI Sectors | C19: P/E | D19: 10y Avg. | E19: Min | F19: Max | G19: Range
B20: Cons. Discretionary | C20: =Calc_Rel!O130 | D20: =Calc_Rel!O129 | E20: =Calc_Rel!O128 | F20: =Calc_Rel!O127
B21: Cons. Staples | C21: =Calc_Rel!P130 | D21: =Calc_Rel!P129 | E21: =Calc_Rel!P128 | F21: =Calc_Rel!P127
B22: Financials | C22: =Calc_Rel!Q130 | D22: =Calc_Rel!Q129 | E22: =Calc_Rel!Q128 | F22: =Calc_Rel!Q127
B23: Technology | C23: =Calc_Rel!R130 | D23: =Calc_Rel!R129 | E23: =Calc_Rel!R128 | F23: =Calc_Rel!R127
B24: Energy | C24: =Calc_Rel!S130 | D24: =Calc_Rel!S129 | E24: =Calc_Rel!S128 | F24: =Calc_Rel!S127
B25: Industrials | C25: =Calc_Rel!T130 | D25: =Calc_Rel!T129 | E25: =Calc_Rel!T128 | F25: =Calc_Rel!T127
B26: Materials | C26: =Calc_Rel!U130 | D26: =Calc_Rel!U129 | E26: =Calc_Rel!U128 | F26: =Calc_Rel!U127
B27: Utilities | C27: =Calc_Rel!V130 | D27: =Calc_Rel!V129 | E27: =Calc_Rel!V128 | F27: =Calc_Rel!V127
B28: Healthcare | C28: =Calc_Rel!W130 | D28: =Calc_Rel!W129 | E28: =Calc_Rel!W128 | F28: =Calc_Rel!W127
B29: Telecom | C29: =Calc_Rel!X130 | D29: =Calc_Rel!X129 | E29: =Calc_Rel!X128 | F29: =Calc_Rel!X127
B30: Ibovespa | C30: =Calc_Rel!N130 | D30: =Calc_Rel!N129 | E30: =Calc_Rel!N128 | F30: =Calc_Rel!N127
B32: Table 3: Brazil vs World – 12M fwd. P/E
B33: Brazil vs. ACWI
B34: MSCI Sectors | C34: P/E | D34: 10y Avg. | E34: Min | F34: Max | G34: Range
B35: Cons. Discretionary | C35: =Calc_Rel!AA130 | D35: =Calc_Rel!AA129 | E35: =Calc_Rel!AA128 | F35: =Calc_Rel!AA127
B36: Cons. Staples | C36: =Calc_Rel!AB130 | D36: =Calc_Rel!AB129 | E36: =Calc_Rel!AB128 | F36: =Calc_Rel!AB127
B37: Financials | C37: =Calc_Rel!AC130 | D37: =Calc_Rel!AC129 | E37: =Calc_Rel!AC128 | F37: =Calc_Rel!AC127
B38: Technology | C38: =Calc_Rel!AD130 | D38: =Calc_Rel!AD129 | E38: =Calc_Rel!AD128 | F38: =Calc_Rel!AD127
B39: Energy | C39: =Calc_Rel!AE130 | D39: =Calc_Rel!AE129 | E39: =Calc_Rel!AE128 | F39: =Calc_Rel!AE127
B40: Industrials | C40: =Calc_Rel!AF130 | D40: =Calc_Rel!AF129 | E40: =Calc_Rel!AF128 | F40: =Calc_Rel!AF127
B41: Materials | C41: =Calc_Rel!AG130 | D41: =Calc_Rel!AG129 | E41: =Calc_Rel!AG128 | F41: =Calc_Rel!AG127
B42: Utilities | C42: =Calc_Rel!AH130 | D42: =Calc_Rel!AH129 | E42: =Calc_Rel!AH128 | F42: =Calc_Rel!AH127
B43: Healthcare | C43: =Calc_Rel!AI130 | D43: =Calc_Rel!AI129 | E43: =Calc_Rel!AI128 | F43: =Calc_Rel!AI127
...

Sheet Relativo (PT)
B2: Tabela 1: Brasil vs Latam – P/L proj. 12m
B3: Brasil vs. Latam
B4: Setores MSCI | C4: P/L Brasil | D4: P/L | E4: Média 10a | F4: Mín | G4: Máx | H4: Faixa
B5: Cons. Discricionário | C5: =Data_BR!C130 | D5: =Calc_Rel!C130 | E5: =Calc_Rel!C129 | F5: =Calc_Rel!C128 | G5: =Calc_Rel!C127
B6: Cons. Básico | C6: =Data_BR!D130 | D6: =Calc_Rel!D130 | E6: =Calc_Rel!D129 | F6: =Calc_Rel!D128 | G6: =Calc_Rel!D127
B7: Financeiro | C7: =Data_BR!E130 | D7: =Calc_Rel!E130 | E7: =Calc_Rel!E129 | F7: =Calc_Rel!E128 | G7: =Calc_Rel!E127
B8: Tecnologia | C8: =Data_BR!F130 | D8: =Calc_Rel!F130 | E8: =Calc_Rel!F129 | F8: =Calc_Rel!F128 | G8: =Calc_Rel!F127
B9: Energia | C9: =Data_BR!G130 | D9: =Calc_Rel!G130 | E9: =Calc_Rel!G129 | F9: =Calc_Rel!G128 | G9: =Calc_Rel!G127
B10: Indústria | C10: =Data_BR!H130 | D10: =Calc_Rel!H130 | E10: =Calc_Rel!H129 | F10: =Calc_Rel!H128 | G10: =Calc_Rel!H127
B11: Materiais | C11: =Data_BR!I130 | D11: =Calc_Rel!I130 | E11: =Calc_Rel!I129 | F11: =Calc_Rel!I128 | G11: =Calc_Rel!I127
B12: Utilities | C12: =Data_BR!J130 | D12: =Calc_Rel!J130 | E12: =Calc_Rel!J129 | F12: =Calc_Rel!J128 | G12: =Calc_Rel!J127
B13: Saúde | C13: =Data_BR!K130 | D13: =Calc_Rel!K130 | E13: =Calc_Rel!K129 | F13: =Calc_Rel!K128 | G13: =Calc_Rel!K127
B14: Telecom | C14: =Data_BR!L130 | D14: =Calc_Rel!L130 | E14: =Calc_Rel!L129 | F14: =Calc_Rel!L128 | G14: =Calc_Rel!L127
B15: Ibovespa | C15: =Data_BR!B130 | D15: =Calc_Rel!B130 | E15: =Calc_Rel!B129 | F15: =Calc_Rel!B128 | G15: =Calc_Rel!B127
B17: Tabela 2: Brasil vs Emergentes – P/L proj. 12m
B18: Brasil vs. Emergentes
B19: Setores MSCI | C19: P/L | D19: Média 10a | E19: Mín | F19: Máx | G19: Faixa
B20: Cons. Discricionário | C20: =Calc_Rel!O130 | D20: =Calc_Rel!O129 | E20: =Calc_Rel!O128 | F20: =Calc_Rel!O127
B21: Cons. Básico | C21: =Calc_Rel!P130 | D21: =Calc_Rel!P129 | E21: =Calc_Rel!P128 | F21: =Calc_Rel!P127
B22: Financeiro | C22: =Calc_Rel!Q130 | D22: =Calc_Rel!Q129 | E22: =Calc_Rel!Q128 | F22: =Calc_Rel!Q127
B23: Tecnologia | C23: =Calc_Rel!R130 | D23: =Calc_Rel!R129 | E23: =Calc_Rel!R128 | F23: =Calc_Rel!R127
B24: Energia | C24: =Calc_Rel!S130 | D24: =Calc_Rel!S129 | E24: =Calc_Rel!S128 | F24: =Calc_Rel!S127
B25: Indústria | C25: =Calc_Rel!T130 | D25: =Calc_Rel!T129 | E25: =Calc_Rel!T128 | F25: =Calc_Rel!T127
B26: Materiais | C26: =Calc_Rel!U130 | D26: =Calc_Rel!U129 | E26: =Calc_Rel!U128 | F26: =Calc_Rel!U127
B27: Utilities | C27: =Calc_Rel!V130 | D27: =Calc_Rel!V129 | E27: =Calc_Rel!V128 | F27: =Calc_Rel!V127
B28: Saúde | C28: =Calc_Rel!W130 | D28: =Calc_Rel!W129 | E28: =Calc_Rel!W128 | F28: =Calc_Rel!W127
B29: Telecom | C29: =Calc_Rel!X130 | D29: =Calc_Rel!X129 | E29: =Calc_Rel!X128 | F29: =Calc_Rel!X127
B30: Ibovespa | C30: =Calc_Rel!N130 | D30: =Calc_Rel!N129 | E30: =Calc_Rel!N128 | F30: =Calc_Rel!N127
B32: Tabela 3: Brasil vs Mundo – P/L proj. 12m
B33: Brasil vs. ACWI
B34: Setores MSCI | C34: P/L | D34: Média 10a | E34: Mín | F34: Máx | G34: Faixa
B35: Cons. Discricionário | C35: =Calc_Rel!AA130 | D35: =Calc_Rel!AA129 | E35: =Calc_Rel!AA128 | F35: =Calc_Rel!AA127
B36: Cons. Básico | C36: =Calc_Rel!AB130 | D36: =Calc_Rel!AB129 | E36: =Calc_Rel!AB128 | F36: =Calc_Rel!AB127
B37: Financeiro | C37: =Calc_Rel!AC130 | D37: =Calc_Rel!AC129 | E37: =Calc_Rel!AC128 | F37: =Calc_Rel!AC127
B38: Tecnologia | C38: =Calc_Rel!AD130 | D38: =Calc_Rel!AD129 | E38: =Calc_Rel!AD128 | F38: =Calc_Rel!AD127
B39: Energia | C39: =Calc_Rel!AE130 | D39: =Calc_Rel!AE129 | E39: =Calc_Rel!AE128 | F39: =Calc_Rel!AE127
B40: Indústria | C40: =Calc_Rel!AF130 | D40: =Calc_Rel!AF129 | E40: =Calc_Rel!AF128 | F40: =Calc_Rel!AF127
B41: Materiais | C41: =Calc_Rel!AG130 | D41: =Calc_Rel!AG129 | E41: =Calc_Rel!AG128 | F41: =Calc_Rel!AG127
B42: Utilities | C42: =Calc_Rel!AH130 | D42: =Calc_Rel!AH129 | E42: =Calc_Rel!AH128 | F42: =Calc_Rel!AH127
B43: Saúde | C43: =Calc_Rel!AI130 | D43: =Calc_Rel!AI129 | E43: =Calc_Rel!AI128 | F43: =Calc_Rel!AI127
...

Sheet Data_BR
A1: Ref. date / Data ref.: | B1: =Painel!$C$4 | C1: Start: | D1: =EOMONTH($B$1,-120)
A3: Date | B3: Brazil | C3: Cons. Discretionary | D3: Cons. Staples | E3: Financials | F3: Technology | G3: Energy | H3: Industrials | I3: Materials | J3: Utilities | K3: Healthcare | L3: Telecom
B4: MXBR Index | C4: MXBR0CD Index | D4: MXBR0CS Index | E4: MXBR0FN Index | F4: MXBR0IT Index | G4: MXBR0EN Index | H4: MXBR0IN Index | I4: MXBR0MT Index | J4: MXBR0UT Index | K4: MXBR0HC Index | L4: MXBR0TC Index
A5: =BDH($B$4,"BEST_PE_RATIO",$D$1,$B$1,"Dates","S","per","cm","Days","A","Fill","P","BEST_DATA_SOURCE_OVERRIDE","bst","CDR","BZ","BEST_FPERIOD_OVERRIDE","bf") | C5: =BDH(C$4,"BEST_PE_RATIO",$D$1,$B$1,"Dates","H","per","cm","Days","A","Fill","P","BEST_DATA_SOURCE_OVERRIDE","bst","CDR","BZ","BEST_FPERIOD_OVERRIDE","bf") | D5: =BDH(D$4,"BEST_PE_RATIO",$D$1,$B$1,"Dates","H","per","cm","Days","A","Fill","P","BEST_DATA_SOURCE_OVERRIDE","bst","CDR","BZ","BEST_FPERIOD_OVERRIDE","bf") | E5: =BDH(E$4,"BEST_PE_RATIO",$D$1,$B$1,"Dates","H","per","cm","Days","A","Fill","P","BEST_DATA_SOURCE_OVERRIDE","bst","CDR","BZ","BEST_FPERIOD_OVERRIDE","bf") | F5: =BDH(F$4,"BEST_PE_RATIO",$D$1,$B$1,"Dates","H","per","cm","Days","A","Fill","P","BEST_DATA_SOURCE_OVERRIDE","bst","CDR","BZ","BEST_FPERIOD_OVERRIDE","bf") | G5: =BDH(G$4,"BEST_PE_RATIO",$D$1,$B$1,"Dates","H","per","cm","Days","A","Fill","P","BEST_DATA_SOURCE_OVERRIDE","bst","CDR","BZ","BEST_FPERIOD_OVERRIDE","bf") | H5: =BDH(H$4,"BEST_PE_RATIO",$D$1,$B$1,"Dates","H","per","cm","Days","A","Fill","P","BEST_DATA_SOURCE_OVERRIDE","bst","CDR","BZ","BEST_FPERIOD_OVERRIDE","bf") | I5: =BDH(I$4,"BEST_PE_RATIO",$D$1,$B$1,"Dates","H","per","cm","Days","A","Fill","P","BEST_DATA_SOURCE_OVERRIDE","bst","CDR","BZ","BEST_FPERIOD_OVERRIDE","bf") | J5: =BDH(J$4,"BEST_PE_RATIO",$D$1,$B$1,"Dates","H","per","cm","Days","A","Fill","P","BEST_DATA_SOURCE_OVERRIDE","bst","CDR","BZ","BEST_FPERIOD_OVERRIDE","bf") | ... L5: =BDH(L$4,"BEST_PE_RATIO",$D$1,$B$1,"Dates","H","per","cm","Days","A","Fill","P","BEST_DATA_SOURCE_OVERRIDE","bst","CDR","BZ","BEST_FPERIOD_OVERRIDE","bf")
A127: Max | B127: =MAX(B5:B125) | C127: =MAX(C5:C125) | D127: =MAX(D5:D125) | E127: =MAX(E5:E125) | F127: =MAX(F5:F125) | G127: =MAX(G5:G125) | H127: =MAX(H5:H125) | I127: =MAX(I5:I125) | ... L127: =MAX(L5:L125)
A128: Min | B128: =MIN(B5:B125) | C128: =MIN(C5:C125) | D128: =MIN(D5:D125) | E128: =MIN(E5:E125) | F128: =MIN(F5:F125) | G128: =MIN(G5:G125) | H128: =MIN(H5:H125) | I128: =MIN(I5:I125) | ... L128: =MIN(L5:L125)
A129: 10y Avg | B129: =AVERAGE(B5:B125) | C129: =AVERAGE(C5:C125) | D129: =AVERAGE(D5:D125) | E129: =AVERAGE(E5:E125) | F129: =AVERAGE(F5:F125) | G129: =AVERAGE(G5:G125) | H129: =AVERAGE(H5:H125) | I129: =AVERAGE(I5:I125) | ... L129: =AVERAGE(L5:L125)
A130: Atual | B130: =B125 | C130: =C125 | D130: =D125 | E130: =E125 | F130: =F125 | G130: =G125 | H130: =H125 | I130: =I125 | ... L130: =L125

Sheet Data_LATAM
A1: Ref. date / Data ref.: | B1: =Painel!$C$4 | C1: Start: | D1: =EOMONTH($B$1,-120)
A3: Date | B3: Latam | C3: Cons. Discretionary | D3: Cons. Staples | E3: Financials | F3: Technology | G3: Energy | H3: Industrials | I3: Materials | J3: Utilities | K3: Healthcare | L3: Telecom
B4: MXLA Index | C4: MXLA0CD Index | D4: MXLA0CS Index | E4: MXLA0FN Index | F4: MXLA0IT Index | G4: MXLA0EN Index | H4: MXLA0IN Index | I4: MXLA0MT Index | J4: MXLA0UT Index | K4: MXLA0HC Index | L4: MXLA0TC Index
A5: =BDH($B$4,"BEST_PE_RATIO",$D$1,$B$1,"Dates","S","per","cm","Days","A","Fill","P","BEST_DATA_SOURCE_OVERRIDE","bst","CDR","BZ","BEST_FPERIOD_OVERRIDE","bf") | C5: =BDH(C$4,"BEST_PE_RATIO",$D$1,$B$1,"Dates","H","per","cm","Days","A","Fill","P","BEST_DATA_SOURCE_OVERRIDE","bst","CDR","BZ","BEST_FPERIOD_OVERRIDE","bf") | D5: =BDH(D$4,"BEST_PE_RATIO",$D$1,$B$1,"Dates","H","per","cm","Days","A","Fill","P","BEST_DATA_SOURCE_OVERRIDE","bst","CDR","BZ","BEST_FPERIOD_OVERRIDE","bf") | E5: =BDH(E$4,"BEST_PE_RATIO",$D$1,$B$1,"Dates","H","per","cm","Days","A","Fill","P","BEST_DATA_SOURCE_OVERRIDE","bst","CDR","BZ","BEST_FPERIOD_OVERRIDE","bf") | F5: =BDH(F$4,"BEST_PE_RATIO",$D$1,$B$1,"Dates","H","per","cm","Days","A","Fill","P","BEST_DATA_SOURCE_OVERRIDE","bst","CDR","BZ","BEST_FPERIOD_OVERRIDE","bf") | G5: =BDH(G$4,"BEST_PE_RATIO",$D$1,$B$1,"Dates","H","per","cm","Days","A","Fill","P","BEST_DATA_SOURCE_OVERRIDE","bst","CDR","BZ","BEST_FPERIOD_OVERRIDE","bf") | H5: =BDH(H$4,"BEST_PE_RATIO",$D$1,$B$1,"Dates","H","per","cm","Days","A","Fill","P","BEST_DATA_SOURCE_OVERRIDE","bst","CDR","BZ","BEST_FPERIOD_OVERRIDE","bf") | I5: =BDH(I$4,"BEST_PE_RATIO",$D$1,$B$1,"Dates","H","per","cm","Days","A","Fill","P","BEST_DATA_SOURCE_OVERRIDE","bst","CDR","BZ","BEST_FPERIOD_OVERRIDE","bf") | J5: =BDH(J$4,"BEST_PE_RATIO",$D$1,$B$1,"Dates","H","per","cm","Days","A","Fill","P","BEST_DATA_SOURCE_OVERRIDE","bst","CDR","BZ","BEST_FPERIOD_OVERRIDE","bf") | ... L5: =BDH(L$4,"BEST_PE_RATIO",$D$1,$B$1,"Dates","H","per","cm","Days","A","Fill","P","BEST_DATA_SOURCE_OVERRIDE","bst","CDR","BZ","BEST_FPERIOD_OVERRIDE","bf")
A127: Max | B127: =MAX(B5:B125) | C127: =MAX(C5:C125) | D127: =MAX(D5:D125) | E127: =MAX(E5:E125) | F127: =MAX(F5:F125) | G127: =MAX(G5:G125) | H127: =MAX(H5:H125) | I127: =MAX(I5:I125) | ... L127: =MAX(L5:L125)
A128: Min | B128: =MIN(B5:B125) | C128: =MIN(C5:C125) | D128: =MIN(D5:D125) | E128: =MIN(E5:E125) | F128: =MIN(F5:F125) | G128: =MIN(G5:G125) | H128: =MIN(H5:H125) | I128: =MIN(I5:I125) | ... L128: =MIN(L5:L125)
A129: 10y Avg | B129: =AVERAGE(B5:B125) | C129: =AVERAGE(C5:C125) | D129: =AVERAGE(D5:D125) | E129: =AVERAGE(E5:E125) | F129: =AVERAGE(F5:F125) | G129: =AVERAGE(G5:G125) | H129: =AVERAGE(H5:H125) | I129: =AVERAGE(I5:I125) | ... L129: =AVERAGE(L5:L125)
A130: Atual | B130: =B125 | C130: =C125 | D130: =D125 | E130: =E125 | F130: =F125 | G130: =G125 | H130: =H125 | I130: =I125 | ... L130: =L125

Sheet Data_EM
A1: Ref. date / Data ref.: | B1: =Painel!$C$4 | C1: Start: | D1: =EOMONTH($B$1,-120)
A3: Date | B3: EM | C3: Cons. Discretionary | D3: Cons. Staples | E3: Financials | F3: Technology | G3: Energy | H3: Industrials | I3: Materials | J3: Utilities | K3: Healthcare | L3: Telecom
B4: MXEF Index | C4: MXEF0CD Index | D4: MXEF0CS Index | E4: MXEF0FN Index | F4: MXEF0IT Index | G4: MXEF0EN Index | H4: MXEF0IN Index | I4: MXEF0MT Index | J4: MXEF0UT Index | K4: MXEF0HC Index | L4: MXEF0TC Index
A5: =BDH($B$4,"BEST_PE_RATIO",$D$1,$B$1,"Dates","S","per","cm","Days","A","Fill","P","BEST_DATA_SOURCE_OVERRIDE","bst","CDR","BZ","BEST_FPERIOD_OVERRIDE","bf") | C5: =BDH(C$4,"BEST_PE_RATIO",$D$1,$B$1,"Dates","H","per","cm","Days","A","Fill","P","BEST_DATA_SOURCE_OVERRIDE","bst","CDR","BZ","BEST_FPERIOD_OVERRIDE","bf") | D5: =BDH(D$4,"BEST_PE_RATIO",$D$1,$B$1,"Dates","H","per","cm","Days","A","Fill","P","BEST_DATA_SOURCE_OVERRIDE","bst","CDR","BZ","BEST_FPERIOD_OVERRIDE","bf") | E5: =BDH(E$4,"BEST_PE_RATIO",$D$1,$B$1,"Dates","H","per","cm","Days","A","Fill","P","BEST_DATA_SOURCE_OVERRIDE","bst","CDR","BZ","BEST_FPERIOD_OVERRIDE","bf") | F5: =BDH(F$4,"BEST_PE_RATIO",$D$1,$B$1,"Dates","H","per","cm","Days","A","Fill","P","BEST_DATA_SOURCE_OVERRIDE","bst","CDR","BZ","BEST_FPERIOD_OVERRIDE","bf") | G5: =BDH(G$4,"BEST_PE_RATIO",$D$1,$B$1,"Dates","H","per","cm","Days","A","Fill","P","BEST_DATA_SOURCE_OVERRIDE","bst","CDR","BZ","BEST_FPERIOD_OVERRIDE","bf") | H5: =BDH(H$4,"BEST_PE_RATIO",$D$1,$B$1,"Dates","H","per","cm","Days","A","Fill","P","BEST_DATA_SOURCE_OVERRIDE","bst","CDR","BZ","BEST_FPERIOD_OVERRIDE","bf") | I5: =BDH(I$4,"BEST_PE_RATIO",$D$1,$B$1,"Dates","H","per","cm","Days","A","Fill","P","BEST_DATA_SOURCE_OVERRIDE","bst","CDR","BZ","BEST_FPERIOD_OVERRIDE","bf") | J5: =BDH(J$4,"BEST_PE_RATIO",$D$1,$B$1,"Dates","H","per","cm","Days","A","Fill","P","BEST_DATA_SOURCE_OVERRIDE","bst","CDR","BZ","BEST_FPERIOD_OVERRIDE","bf") | ... L5: =BDH(L$4,"BEST_PE_RATIO",$D$1,$B$1,"Dates","H","per","cm","Days","A","Fill","P","BEST_DATA_SOURCE_OVERRIDE","bst","CDR","BZ","BEST_FPERIOD_OVERRIDE","bf")
A127: Max | B127: =MAX(B5:B125) | C127: =MAX(C5:C125) | D127: =MAX(D5:D125) | E127: =MAX(E5:E125) | F127: =MAX(F5:F125) | G127: =MAX(G5:G125) | H127: =MAX(H5:H125) | I127: =MAX(I5:I125) | ... L127: =MAX(L5:L125)
A128: Min | B128: =MIN(B5:B125) | C128: =MIN(C5:C125) | D128: =MIN(D5:D125) | E128: =MIN(E5:E125) | F128: =MIN(F5:F125) | G128: =MIN(G5:G125) | H128: =MIN(H5:H125) | I128: =MIN(I5:I125) | ... L128: =MIN(L5:L125)
A129: 10y Avg | B129: =AVERAGE(B5:B125) | C129: =AVERAGE(C5:C125) | D129: =AVERAGE(D5:D125) | E129: =AVERAGE(E5:E125) | F129: =AVERAGE(F5:F125) | G129: =AVERAGE(G5:G125) | H129: =AVERAGE(H5:H125) | I129: =AVERAGE(I5:I125) | ... L129: =AVERAGE(L5:L125)
A130: Atual | B130: =B125 | C130: =C125 | D130: =D125 | E130: =E125 | F130: =F125 | G130: =G125 | H130: =H125 | I130: =I125 | ... L130: =L125

Sheet Data_World
A1: Ref. date / Data ref.: | B1: =Painel!$C$4 | C1: Start: | D1: =EOMONTH($B$1,-120)
A3: Date | B3: World | C3: Cons. Discretionary | D3: Cons. Staples | E3: Financials | F3: Technology | G3: Energy | H3: Industrials | I3: Materials | J3: Utilities | K3: Healthcare | L3: Telecom
B4: MXWD Index | C4: MXWD0CD Index | D4: MXWD0CS Index | E4: MXWD0FN Index | F4: MXWD0IT Index | G4: MXWD0EN Index | H4: MXWD0IN Index | I4: MXWD0MT Index | J4: MXWD0UT Index | K4: MXWD0HC Index | L4: MXWD0TC Index
A5: =BDH($B$4,"BEST_PE_RATIO",$D$1,$B$1,"Dates","S","per","cm","Days","A","Fill","P","BEST_DATA_SOURCE_OVERRIDE","bst","CDR","BZ","BEST_FPERIOD_OVERRIDE","bf") | C5: =BDH(C$4,"BEST_PE_RATIO",$D$1,$B$1,"Dates","H","per","cm","Days","A","Fill","P","BEST_DATA_SOURCE_OVERRIDE","bst","CDR","BZ","BEST_FPERIOD_OVERRIDE","bf") | D5: =BDH(D$4,"BEST_PE_RATIO",$D$1,$B$1,"Dates","H","per","cm","Days","A","Fill","P","BEST_DATA_SOURCE_OVERRIDE","bst","CDR","BZ","BEST_FPERIOD_OVERRIDE","bf") | E5: =BDH(E$4,"BEST_PE_RATIO",$D$1,$B$1,"Dates","H","per","cm","Days","A","Fill","P","BEST_DATA_SOURCE_OVERRIDE","bst","CDR","BZ","BEST_FPERIOD_OVERRIDE","bf") | F5: =BDH(F$4,"BEST_PE_RATIO",$D$1,$B$1,"Dates","H","per","cm","Days","A","Fill","P","BEST_DATA_SOURCE_OVERRIDE","bst","CDR","BZ","BEST_FPERIOD_OVERRIDE","bf") | G5: =BDH(G$4,"BEST_PE_RATIO",$D$1,$B$1,"Dates","H","per","cm","Days","A","Fill","P","BEST_DATA_SOURCE_OVERRIDE","bst","CDR","BZ","BEST_FPERIOD_OVERRIDE","bf") | H5: =BDH(H$4,"BEST_PE_RATIO",$D$1,$B$1,"Dates","H","per","cm","Days","A","Fill","P","BEST_DATA_SOURCE_OVERRIDE","bst","CDR","BZ","BEST_FPERIOD_OVERRIDE","bf") | I5: =BDH(I$4,"BEST_PE_RATIO",$D$1,$B$1,"Dates","H","per","cm","Days","A","Fill","P","BEST_DATA_SOURCE_OVERRIDE","bst","CDR","BZ","BEST_FPERIOD_OVERRIDE","bf") | J5: =BDH(J$4,"BEST_PE_RATIO",$D$1,$B$1,"Dates","H","per","cm","Days","A","Fill","P","BEST_DATA_SOURCE_OVERRIDE","bst","CDR","BZ","BEST_FPERIOD_OVERRIDE","bf") | ... L5: =BDH(L$4,"BEST_PE_RATIO",$D$1,$B$1,"Dates","H","per","cm","Days","A","Fill","P","BEST_DATA_SOURCE_OVERRIDE","bst","CDR","BZ","BEST_FPERIOD_OVERRIDE","bf")
A127: Max | B127: =MAX(B5:B125) | C127: =MAX(C5:C125) | D127: =MAX(D5:D125) | E127: =MAX(E5:E125) | F127: =MAX(F5:F125) | G127: =MAX(G5:G125) | H127: =MAX(H5:H125) | I127: =MAX(I5:I125) | ... L127: =MAX(L5:L125)
A128: Min | B128: =MIN(B5:B125) | C128: =MIN(C5:C125) | D128: =MIN(D5:D125) | E128: =MIN(E5:E125) | F128: =MIN(F5:F125) | G128: =MIN(G5:G125) | H128: =MIN(H5:H125) | I128: =MIN(I5:I125) | ... L128: =MIN(L5:L125)
A129: 10y Avg | B129: =AVERAGE(B5:B125) | C129: =AVERAGE(C5:C125) | D129: =AVERAGE(D5:D125) | E129: =AVERAGE(E5:E125) | F129: =AVERAGE(F5:F125) | G129: =AVERAGE(G5:G125) | H129: =AVERAGE(H5:H125) | I129: =AVERAGE(I5:I125) | ... L129: =AVERAGE(L5:L125)
A130: Atual | B130: =B125 | C130: =C125 | D130: =D125 | E130: =E125 | F130: =F125 | G130: =G125 | H130: =H125 | I130: =I125 | ... L130: =L125

Sheet Calc_Rel
A1: Relative fwd P/E series = Brazil / Region (index + sectors)
B2: vs Latam | N2: vs EM | Z2: vs World
B3: Index | C3: Cons. Discretionary | D3: Cons. Staples | E3: Financials | F3: Technology | G3: Energy | H3: Industrials | I3: Materials | J3: Utilities | K3: Healthcare | L3: Telecom | N3: Index | O3: Cons. Discretionary | P3: Cons. Staples | Q3: Financials | R3: Technology | S3: Energy | T3: Industrials | U3: Materials | V3: Utilities | W3: Healthcare | X3: Telecom | Z3: Index | AA3: Cons. Discretionary | AB3: Cons. Staples | AC3: Financials | AD3: Technology | AE3: Energy | AF3: Industrials | AG3: Materials | AH3: Utilities | AI3: Healthcare | AJ3: Telecom
A5: =Data_BR!A5 | B5: =IFERROR(Data_BR!B5/Data_LATAM!B5,"") | C5: =IFERROR(Data_BR!C5/Data_LATAM!C5,"") | D5: =IFERROR(Data_BR!D5/Data_LATAM!D5,"") | E5: =IFERROR(Data_BR!E5/Data_LATAM!E5,"") | F5: =IFERROR(Data_BR!F5/Data_LATAM!F5,"") | G5: =IFERROR(Data_BR!G5/Data_LATAM!G5,"") | H5: =IFERROR(Data_BR!H5/Data_LATAM!H5,"") | I5: =IFERROR(Data_BR!I5/Data_LATAM!I5,"") | ... L5: =IFERROR(Data_BR!L5/Data_LATAM!L5,"") | N5: =IFERROR(Data_BR!B5/Data_EM!B5,"") | O5: =IFERROR(Data_BR!C5/Data_EM!C5,"") | P5: =IFERROR(Data_BR!D5/Data_EM!D5,"") | Q5: =IFERROR(Data_BR!E5/Data_EM!E5,"") | R5: =IFERROR(Data_BR!F5/Data_EM!F5,"") | S5: =IFERROR(Data_BR!G5/Data_EM!G5,"") | T5: =IFERROR(Data_BR!H5/Data_EM!H5,"") | U5: =IFERROR(Data_BR!I5/Data_EM!I5,"") | ... X5: =IFERROR(Data_BR!L5/Data_EM!L5,"") | Z5: =IFERROR(Data_BR!B5/Data_World!B5,"") | AA5: =IFERROR(Data_BR!C5/Data_World!C5,"") | AB5: =IFERROR(Data_BR!D5/Data_World!D5,"") | AC5: =IFERROR(Data_BR!E5/Data_World!E5,"") | AD5: =IFERROR(Data_BR!F5/Data_World!F5,"") | AE5: =IFERROR(Data_BR!G5/Data_World!G5,"") | AF5: =IFERROR(Data_BR!H5/Data_World!H5,"") | AG5: =IFERROR(Data_BR!I5/Data_World!I5,"") | ... AJ5: =IFERROR(Data_BR!L5/Data_World!L5,"")
A6: =Data_BR!A6 | B6: =IFERROR(Data_BR!B6/Data_LATAM!B6,"") | C6: =IFERROR(Data_BR!C6/Data_LATAM!C6,"") | D6: =IFERROR(Data_BR!D6/Data_LATAM!D6,"") | E6: =IFERROR(Data_BR!E6/Data_LATAM!E6,"") | F6: =IFERROR(Data_BR!F6/Data_LATAM!F6,"") | G6: =IFERROR(Data_BR!G6/Data_LATAM!G6,"") | H6: =IFERROR(Data_BR!H6/Data_LATAM!H6,"") | I6: =IFERROR(Data_BR!I6/Data_LATAM!I6,"") | ... L6: =IFERROR(Data_BR!L6/Data_LATAM!L6,"") | N6: =IFERROR(Data_BR!B6/Data_EM!B6,"") | O6: =IFERROR(Data_BR!C6/Data_EM!C6,"") | P6: =IFERROR(Data_BR!D6/Data_EM!D6,"") | Q6: =IFERROR(Data_BR!E6/Data_EM!E6,"") | R6: =IFERROR(Data_BR!F6/Data_EM!F6,"") | S6: =IFERROR(Data_BR!G6/Data_EM!G6,"") | T6: =IFERROR(Data_BR!H6/Data_EM!H6,"") | U6: =IFERROR(Data_BR!I6/Data_EM!I6,"") | ... X6: =IFERROR(Data_BR!L6/Data_EM!L6,"") | Z6: =IFERROR(Data_BR!B6/Data_World!B6,"") | AA6: =IFERROR(Data_BR!C6/Data_World!C6,"") | AB6: =IFERROR(Data_BR!D6/Data_World!D6,"") | AC6: =IFERROR(Data_BR!E6/Data_World!E6,"") | AD6: =IFERROR(Data_BR!F6/Data_World!F6,"") | AE6: =IFERROR(Data_BR!G6/Data_World!G6,"") | AF6: =IFERROR(Data_BR!H6/Data_World!H6,"") | AG6: =IFERROR(Data_BR!I6/Data_World!I6,"") | ... AJ6: =IFERROR(Data_BR!L6/Data_World!L6,"")
A7: =Data_BR!A7 | B7: =IFERROR(Data_BR!B7/Data_LATAM!B7,"") | C7: =IFERROR(Data_BR!C7/Data_LATAM!C7,"") | D7: =IFERROR(Data_BR!D7/Data_LATAM!D7,"") | E7: =IFERROR(Data_BR!E7/Data_LATAM!E7,"") | F7: =IFERROR(Data_BR!F7/Data_LATAM!F7,"") | G7: =IFERROR(Data_BR!G7/Data_LATAM!G7,"") | H7: =IFERROR(Data_BR!H7/Data_LATAM!H7,"") | I7: =IFERROR(Data_BR!I7/Data_LATAM!I7,"") | ... L7: =IFERROR(Data_BR!L7/Data_LATAM!L7,"") | N7: =IFERROR(Data_BR!B7/Data_EM!B7,"") | O7: =IFERROR(Data_BR!C7/Data_EM!C7,"") | P7: =IFERROR(Data_BR!D7/Data_EM!D7,"") | Q7: =IFERROR(Data_BR!E7/Data_EM!E7,"") | R7: =IFERROR(Data_BR!F7/Data_EM!F7,"") | S7: =IFERROR(Data_BR!G7/Data_EM!G7,"") | T7: =IFERROR(Data_BR!H7/Data_EM!H7,"") | U7: =IFERROR(Data_BR!I7/Data_EM!I7,"") | ... X7: =IFERROR(Data_BR!L7/Data_EM!L7,"") | Z7: =IFERROR(Data_BR!B7/Data_World!B7,"") | AA7: =IFERROR(Data_BR!C7/Data_World!C7,"") | AB7: =IFERROR(Data_BR!D7/Data_World!D7,"") | AC7: =IFERROR(Data_BR!E7/Data_World!E7,"") | AD7: =IFERROR(Data_BR!F7/Data_World!F7,"") | AE7: =IFERROR(Data_BR!G7/Data_World!G7,"") | AF7: =IFERROR(Data_BR!H7/Data_World!H7,"") | AG7: =IFERROR(Data_BR!I7/Data_World!I7,"") | ... AJ7: =IFERROR(Data_BR!L7/Data_World!L7,"")
A8: =Data_BR!A8 | B8: =IFERROR(Data_BR!B8/Data_LATAM!B8,"") | C8: =IFERROR(Data_BR!C8/Data_LATAM!C8,"") | D8: =IFERROR(Data_BR!D8/Data_LATAM!D8,"") | E8: =IFERROR(Data_BR!E8/Data_LATAM!E8,"") | F8: =IFERROR(Data_BR!F8/Data_LATAM!F8,"") | G8: =IFERROR(Data_BR!G8/Data_LATAM!G8,"") | H8: =IFERROR(Data_BR!H8/Data_LATAM!H8,"") | I8: =IFERROR(Data_BR!I8/Data_LATAM!I8,"") | ... L8: =IFERROR(Data_BR!L8/Data_LATAM!L8,"") | N8: =IFERROR(Data_BR!B8/Data_EM!B8,"") | O8: =IFERROR(Data_BR!C8/Data_EM!C8,"") | P8: =IFERROR(Data_BR!D8/Data_EM!D8,"") | Q8: =IFERROR(Data_BR!E8/Data_EM!E8,"") | R8: =IFERROR(Data_BR!F8/Data_EM!F8,"") | S8: =IFERROR(Data_BR!G8/Data_EM!G8,"") | T8: =IFERROR(Data_BR!H8/Data_EM!H8,"") | U8: =IFERROR(Data_BR!I8/Data_EM!I8,"") | ... X8: =IFERROR(Data_BR!L8/Data_EM!L8,"") | Z8: =IFERROR(Data_BR!B8/Data_World!B8,"") | AA8: =IFERROR(Data_BR!C8/Data_World!C8,"") | AB8: =IFERROR(Data_BR!D8/Data_World!D8,"") | AC8: =IFERROR(Data_BR!E8/Data_World!E8,"") | AD8: =IFERROR(Data_BR!F8/Data_World!F8,"") | AE8: =IFERROR(Data_BR!G8/Data_World!G8,"") | AF8: =IFERROR(Data_BR!H8/Data_World!H8,"") | AG8: =IFERROR(Data_BR!I8/Data_World!I8,"") | ... AJ8: =IFERROR(Data_BR!L8/Data_World!L8,"")
A9: =Data_BR!A9 | B9: =IFERROR(Data_BR!B9/Data_LATAM!B9,"") | C9: =IFERROR(Data_BR!C9/Data_LATAM!C9,"") | D9: =IFERROR(Data_BR!D9/Data_LATAM!D9,"") | E9: =IFERROR(Data_BR!E9/Data_LATAM!E9,"") | F9: =IFERROR(Data_BR!F9/Data_LATAM!F9,"") | G9: =IFERROR(Data_BR!G9/Data_LATAM!G9,"") | H9: =IFERROR(Data_BR!H9/Data_LATAM!H9,"") | I9: =IFERROR(Data_BR!I9/Data_LATAM!I9,"") | ... L9: =IFERROR(Data_BR!L9/Data_LATAM!L9,"") | N9: =IFERROR(Data_BR!B9/Data_EM!B9,"") | O9: =IFERROR(Data_BR!C9/Data_EM!C9,"") | P9: =IFERROR(Data_BR!D9/Data_EM!D9,"") | Q9: =IFERROR(Data_BR!E9/Data_EM!E9,"") | R9: =IFERROR(Data_BR!F9/Data_EM!F9,"") | S9: =IFERROR(Data_BR!G9/Data_EM!G9,"") | T9: =IFERROR(Data_BR!H9/Data_EM!H9,"") | U9: =IFERROR(Data_BR!I9/Data_EM!I9,"") | ... X9: =IFERROR(Data_BR!L9/Data_EM!L9,"") | Z9: =IFERROR(Data_BR!B9/Data_World!B9,"") | AA9: =IFERROR(Data_BR!C9/Data_World!C9,"") | AB9: =IFERROR(Data_BR!D9/Data_World!D9,"") | AC9: =IFERROR(Data_BR!E9/Data_World!E9,"") | AD9: =IFERROR(Data_BR!F9/Data_World!F9,"") | AE9: =IFERROR(Data_BR!G9/Data_World!G9,"") | AF9: =IFERROR(Data_BR!H9/Data_World!H9,"") | AG9: =IFERROR(Data_BR!I9/Data_World!I9,"") | ... AJ9: =IFERROR(Data_BR!L9/Data_World!L9,"")
A10: =Data_BR!A10 | B10: =IFERROR(Data_BR!B10/Data_LATAM!B10,"") | C10: =IFERROR(Data_BR!C10/Data_LATAM!C10,"") | D10: =IFERROR(Data_BR!D10/Data_LATAM!D10,"") | E10: =IFERROR(Data_BR!E10/Data_LATAM!E10,"") | F10: =IFERROR(Data_BR!F10/Data_LATAM!F10,"") | G10: =IFERROR(Data_BR!G10/Data_LATAM!G10,"") | H10: =IFERROR(Data_BR!H10/Data_LATAM!H10,"") | I10: =IFERROR(Data_BR!I10/Data_LATAM!I10,"") | ... L10: =IFERROR(Data_BR!L10/Data_LATAM!L10,"") | N10: =IFERROR(Data_BR!B10/Data_EM!B10,"") | O10: =IFERROR(Data_BR!C10/Data_EM!C10,"") | P10: =IFERROR(Data_BR!D10/Data_EM!D10,"") | Q10: =IFERROR(Data_BR!E10/Data_EM!E10,"") | R10: =IFERROR(Data_BR!F10/Data_EM!F10,"") | S10: =IFERROR(Data_BR!G10/Data_EM!G10,"") | T10: =IFERROR(Data_BR!H10/Data_EM!H10,"") | U10: =IFERROR(Data_BR!I10/Data_EM!I10,"") | ... X10: =IFERROR(Data_BR!L10/Data_EM!L10,"") | Z10: =IFERROR(Data_BR!B10/Data_World!B10,"") | AA10: =IFERROR(Data_BR!C10/Data_World!C10,"") | AB10: =IFERROR(Data_BR!D10/Data_World!D10,"") | AC10: =IFERROR(Data_BR!E10/Data_World!E10,"") | AD10: =IFERROR(Data_BR!F10/Data_World!F10,"") | AE10: =IFERROR(Data_BR!G10/Data_World!G10,"") | AF10: =IFERROR(Data_BR!H10/Data_World!H10,"") | AG10: =IFERROR(Data_BR!I10/Data_World!I10,"") | ... AJ10: =IFERROR(Data_BR!L10/Data_World!L10,"")
A11: =Data_BR!A11 | B11: =IFERROR(Data_BR!B11/Data_LATAM!B11,"") | C11: =IFERROR(Data_BR!C11/Data_LATAM!C11,"") | D11: =IFERROR(Data_BR!D11/Data_LATAM!D11,"") | E11: =IFERROR(Data_BR!E11/Data_LATAM!E11,"") | F11: =IFERROR(Data_BR!F11/Data_LATAM!F11,"") | G11: =IFERROR(Data_BR!G11/Data_LATAM!G11,"") | H11: =IFERROR(Data_BR!H11/Data_LATAM!H11,"") | I11: =IFERROR(Data_BR!I11/Data_LATAM!I11,"") | ... L11: =IFERROR(Data_BR!L11/Data_LATAM!L11,"") | N11: =IFERROR(Data_BR!B11/Data_EM!B11,"") | O11: =IFERROR(Data_BR!C11/Data_EM!C11,"") | P11: =IFERROR(Data_BR!D11/Data_EM!D11,"") | Q11: =IFERROR(Data_BR!E11/Data_EM!E11,"") | R11: =IFERROR(Data_BR!F11/Data_EM!F11,"") | S11: =IFERROR(Data_BR!G11/Data_EM!G11,"") | T11: =IFERROR(Data_BR!H11/Data_EM!H11,"") | U11: =IFERROR(Data_BR!I11/Data_EM!I11,"") | ... X11: =IFERROR(Data_BR!L11/Data_EM!L11,"") | Z11: =IFERROR(Data_BR!B11/Data_World!B11,"") | AA11: =IFERROR(Data_BR!C11/Data_World!C11,"") | AB11: =IFERROR(Data_BR!D11/Data_World!D11,"") | AC11: =IFERROR(Data_BR!E11/Data_World!E11,"") | AD11: =IFERROR(Data_BR!F11/Data_World!F11,"") | AE11: =IFERROR(Data_BR!G11/Data_World!G11,"") | AF11: =IFERROR(Data_BR!H11/Data_World!H11,"") | AG11: =IFERROR(Data_BR!I11/Data_World!I11,"") | ... AJ11: =IFERROR(Data_BR!L11/Data_World!L11,"")
A12: =Data_BR!A12 | B12: =IFERROR(Data_BR!B12/Data_LATAM!B12,"") | C12: =IFERROR(Data_BR!C12/Data_LATAM!C12,"") | D12: =IFERROR(Data_BR!D12/Data_LATAM!D12,"") | E12: =IFERROR(Data_BR!E12/Data_LATAM!E12,"") | F12: =IFERROR(Data_BR!F12/Data_LATAM!F12,"") | G12: =IFERROR(Data_BR!G12/Data_LATAM!G12,"") | H12: =IFERROR(Data_BR!H12/Data_LATAM!H12,"") | I12: =IFERROR(Data_BR!I12/Data_LATAM!I12,"") | ... L12: =IFERROR(Data_BR!L12/Data_LATAM!L12,"") | N12: =IFERROR(Data_BR!B12/Data_EM!B12,"") | O12: =IFERROR(Data_BR!C12/Data_EM!C12,"") | P12: =IFERROR(Data_BR!D12/Data_EM!D12,"") | Q12: =IFERROR(Data_BR!E12/Data_EM!E12,"") | R12: =IFERROR(Data_BR!F12/Data_EM!F12,"") | S12: =IFERROR(Data_BR!G12/Data_EM!G12,"") | T12: =IFERROR(Data_BR!H12/Data_EM!H12,"") | U12: =IFERROR(Data_BR!I12/Data_EM!I12,"") | ... X12: =IFERROR(Data_BR!L12/Data_EM!L12,"") | Z12: =IFERROR(Data_BR!B12/Data_World!B12,"") | AA12: =IFERROR(Data_BR!C12/Data_World!C12,"") | AB12: =IFERROR(Data_BR!D12/Data_World!D12,"") | AC12: =IFERROR(Data_BR!E12/Data_World!E12,"") | AD12: =IFERROR(Data_BR!F12/Data_World!F12,"") | AE12: =IFERROR(Data_BR!G12/Data_World!G12,"") | AF12: =IFERROR(Data_BR!H12/Data_World!H12,"") | AG12: =IFERROR(Data_BR!I12/Data_World!I12,"") | ... AJ12: =IFERROR(Data_BR!L12/Data_World!L12,"")
A13: =Data_BR!A13 | B13: =IFERROR(Data_BR!B13/Data_LATAM!B13,"") | C13: =IFERROR(Data_BR!C13/Data_LATAM!C13,"") | D13: =IFERROR(Data_BR!D13/Data_LATAM!D13,"") | E13: =IFERROR(Data_BR!E13/Data_LATAM!E13,"") | F13: =IFERROR(Data_BR!F13/Data_LATAM!F13,"") | G13: =IFERROR(Data_BR!G13/Data_LATAM!G13,"") | H13: =IFERROR(Data_BR!H13/Data_LATAM!H13,"") | I13: =IFERROR(Data_BR!I13/Data_LATAM!I13,"") | ... L13: =IFERROR(Data_BR!L13/Data_LATAM!L13,"") | N13: =IFERROR(Data_BR!B13/Data_EM!B13,"") | O13: =IFERROR(Data_BR!C13/Data_EM!C13,"") | P13: =IFERROR(Data_BR!D13/Data_EM!D13,"") | Q13: =IFERROR(Data_BR!E13/Data_EM!E13,"") | R13: =IFERROR(Data_BR!F13/Data_EM!F13,"") | S13: =IFERROR(Data_BR!G13/Data_EM!G13,"") | T13: =IFERROR(Data_BR!H13/Data_EM!H13,"") | U13: =IFERROR(Data_BR!I13/Data_EM!I13,"") | ... X13: =IFERROR(Data_BR!L13/Data_EM!L13,"") | Z13: =IFERROR(Data_BR!B13/Data_World!B13,"") | AA13: =IFERROR(Data_BR!C13/Data_World!C13,"") | AB13: =IFERROR(Data_BR!D13/Data_World!D13,"") | AC13: =IFERROR(Data_BR!E13/Data_World!E13,"") | AD13: =IFERROR(Data_BR!F13/Data_World!F13,"") | AE13: =IFERROR(Data_BR!G13/Data_World!G13,"") | AF13: =IFERROR(Data_BR!H13/Data_World!H13,"") | AG13: =IFERROR(Data_BR!I13/Data_World!I13,"") | ... AJ13: =IFERROR(Data_BR!L13/Data_World!L13,"")
A14: =Data_BR!A14 | B14: =IFERROR(Data_BR!B14/Data_LATAM!B14,"") | C14: =IFERROR(Data_BR!C14/Data_LATAM!C14,"") | D14: =IFERROR(Data_BR!D14/Data_LATAM!D14,"") | E14: =IFERROR(Data_BR!E14/Data_LATAM!E14,"") | F14: =IFERROR(Data_BR!F14/Data_LATAM!F14,"") | G14: =IFERROR(Data_BR!G14/Data_LATAM!G14,"") | H14: =IFERROR(Data_BR!H14/Data_LATAM!H14,"") | I14: =IFERROR(Data_BR!I14/Data_LATAM!I14,"") | ... L14: =IFERROR(Data_BR!L14/Data_LATAM!L14,"") | N14: =IFERROR(Data_BR!B14/Data_EM!B14,"") | O14: =IFERROR(Data_BR!C14/Data_EM!C14,"") | P14: =IFERROR(Data_BR!D14/Data_EM!D14,"") | Q14: =IFERROR(Data_BR!E14/Data_EM!E14,"") | R14: =IFERROR(Data_BR!F14/Data_EM!F14,"") | S14: =IFERROR(Data_BR!G14/Data_EM!G14,"") | T14: =IFERROR(Data_BR!H14/Data_EM!H14,"") | U14: =IFERROR(Data_BR!I14/Data_EM!I14,"") | ... X14: =IFERROR(Data_BR!L14/Data_EM!L14,"") | Z14: =IFERROR(Data_BR!B14/Data_World!B14,"") | AA14: =IFERROR(Data_BR!C14/Data_World!C14,"") | AB14: =IFERROR(Data_BR!D14/Data_World!D14,"") | AC14: =IFERROR(Data_BR!E14/Data_World!E14,"") | AD14: =IFERROR(Data_BR!F14/Data_World!F14,"") | AE14: =IFERROR(Data_BR!G14/Data_World!G14,"") | AF14: =IFERROR(Data_BR!H14/Data_World!H14,"") | AG14: =IFERROR(Data_BR!I14/Data_World!I14,"") | ... AJ14: =IFERROR(Data_BR!L14/Data_World!L14,"")
A15: =Data_BR!A15 | B15: =IFERROR(Data_BR!B15/Data_LATAM!B15,"") | C15: =IFERROR(Data_BR!C15/Data_LATAM!C15,"") | D15: =IFERROR(Data_BR!D15/Data_LATAM!D15,"") | E15: =IFERROR(Data_BR!E15/Data_LATAM!E15,"") | F15: =IFERROR(Data_BR!F15/Data_LATAM!F15,"") | G15: =IFERROR(Data_BR!G15/Data_LATAM!G15,"") | H15: =IFERROR(Data_BR!H15/Data_LATAM!H15,"") | I15: =IFERROR(Data_BR!I15/Data_LATAM!I15,"") | ... L15: =IFERROR(Data_BR!L15/Data_LATAM!L15,"") | N15: =IFERROR(Data_BR!B15/Data_EM!B15,"") | O15: =IFERROR(Data_BR!C15/Data_EM!C15,"") | P15: =IFERROR(Data_BR!D15/Data_EM!D15,"") | Q15: =IFERROR(Data_BR!E15/Data_EM!E15,"") | R15: =IFERROR(Data_BR!F15/Data_EM!F15,"") | S15: =IFERROR(Data_BR!G15/Data_EM!G15,"") | T15: =IFERROR(Data_BR!H15/Data_EM!H15,"") | U15: =IFERROR(Data_BR!I15/Data_EM!I15,"") | ... X15: =IFERROR(Data_BR!L15/Data_EM!L15,"") | Z15: =IFERROR(Data_BR!B15/Data_World!B15,"") | AA15: =IFERROR(Data_BR!C15/Data_World!C15,"") | AB15: =IFERROR(Data_BR!D15/Data_World!D15,"") | AC15: =IFERROR(Data_BR!E15/Data_World!E15,"") | AD15: =IFERROR(Data_BR!F15/Data_World!F15,"") | AE15: =IFERROR(Data_BR!G15/Data_World!G15,"") | AF15: =IFERROR(Data_BR!H15/Data_World!H15,"") | AG15: =IFERROR(Data_BR!I15/Data_World!I15,"") | ... AJ15: =IFERROR(Data_BR!L15/Data_World!L15,"")
A16: =Data_BR!A16 | B16: =IFERROR(Data_BR!B16/Data_LATAM!B16,"") | C16: =IFERROR(Data_BR!C16/Data_LATAM!C16,"") | D16: =IFERROR(Data_BR!D16/Data_LATAM!D16,"") | E16: =IFERROR(Data_BR!E16/Data_LATAM!E16,"") | F16: =IFERROR(Data_BR!F16/Data_LATAM!F16,"") | G16: =IFERROR(Data_BR!G16/Data_LATAM!G16,"") | H16: =IFERROR(Data_BR!H16/Data_LATAM!H16,"") | I16: =IFERROR(Data_BR!I16/Data_LATAM!I16,"") | ... L16: =IFERROR(Data_BR!L16/Data_LATAM!L16,"") | N16: =IFERROR(Data_BR!B16/Data_EM!B16,"") | O16: =IFERROR(Data_BR!C16/Data_EM!C16,"") | P16: =IFERROR(Data_BR!D16/Data_EM!D16,"") | Q16: =IFERROR(Data_BR!E16/Data_EM!E16,"") | R16: =IFERROR(Data_BR!F16/Data_EM!F16,"") | S16: =IFERROR(Data_BR!G16/Data_EM!G16,"") | T16: =IFERROR(Data_BR!H16/Data_EM!H16,"") | U16: =IFERROR(Data_BR!I16/Data_EM!I16,"") | ... X16: =IFERROR(Data_BR!L16/Data_EM!L16,"") | Z16: =IFERROR(Data_BR!B16/Data_World!B16,"") | AA16: =IFERROR(Data_BR!C16/Data_World!C16,"") | AB16: =IFERROR(Data_BR!D16/Data_World!D16,"") | AC16: =IFERROR(Data_BR!E16/Data_World!E16,"") | AD16: =IFERROR(Data_BR!F16/Data_World!F16,"") | AE16: =IFERROR(Data_BR!G16/Data_World!G16,"") | AF16: =IFERROR(Data_BR!H16/Data_World!H16,"") | AG16: =IFERROR(Data_BR!I16/Data_World!I16,"") | ... AJ16: =IFERROR(Data_BR!L16/Data_World!L16,"")
... A125: =Data_BR!A125 | B125: =IFERROR(Data_BR!B125/Data_LATAM!B125,"") | C125: =IFERROR(Data_BR!C125/Data_LATAM!C125,"") | D125: =IFERROR(Data_BR!D125/Data_LATAM!D125,"") | E125: =IFERROR(Data_BR!E125/Data_LATAM!E125,"") | F125: =IFERROR(Data_BR!F125/Data_LATAM!F125,"") | G125: =IFERROR(Data_BR!G125/Data_LATAM!G125,"") | H125: =IFERROR(Data_BR!H125/Data_LATAM!H125,"") | I125: =IFERROR(Data_BR!I125/Data_LATAM!I125,"") | ... L125: =IFERROR(Data_BR!L125/Data_LATAM!L125,"") | N125: =IFERROR(Data_BR!B125/Data_EM!B125,"") | O125: =IFERROR(Data_BR!C125/Data_EM!C125,"") | P125: =IFERROR(Data_BR!D125/Data_EM!D125,"") | Q125: =IFERROR(Data_BR!E125/Data_EM!E125,"") | R125: =IFERROR(Data_BR!F125/Data_EM!F125,"") | S125: =IFERROR(Data_BR!G125/Data_EM!G125,"") | T125: =IFERROR(Data_BR!H125/Data_EM!H125,"") | U125: =IFERROR(Data_BR!I125/Data_EM!I125,"") | ... X125: =IFERROR(Data_BR!L125/Data_EM!L125,"") | Z125: =IFERROR(Data_BR!B125/Data_World!B125,"") | AA125: =IFERROR(Data_BR!C125/Data_World!C125,"") | AB125: =IFERROR(Data_BR!D125/Data_World!D125,"") | AC125: =IFERROR(Data_BR!E125/Data_World!E125,"") | AD125: =IFERROR(Data_BR!F125/Data_World!F125,"") | AE125: =IFERROR(Data_BR!G125/Data_World!G125,"") | AF125: =IFERROR(Data_BR!H125/Data_World!H125,"") | AG125: =IFERROR(Data_BR!I125/Data_World!I125,"") | ... AJ125: =IFERROR(Data_BR!L125/Data_World!L125,"")
B127: =MAX(B5:B125) | C127: =MAX(C5:C125) | D127: =MAX(D5:D125) | E127: =MAX(E5:E125) | F127: =MAX(F5:F125) | G127: =MAX(G5:G125) | H127: =MAX(H5:H125) | I127: =MAX(I5:I125) | ... L127: =MAX(L5:L125) | N127: =MAX(N5:N125) | O127: =MAX(O5:O125) | P127: =MAX(P5:P125) | Q127: =MAX(Q5:Q125) | R127: =MAX(R5:R125) | S127: =MAX(S5:S125) | T127: =MAX(T5:T125) | U127: =MAX(U5:U125) | ... X127: =MAX(X5:X125) | Z127: =MAX(Z5:Z125) | AA127: =MAX(AA5:AA125) | AB127: =MAX(AB5:AB125) | AC127: =MAX(AC5:AC125) | AD127: =MAX(AD5:AD125) | AE127: =MAX(AE5:AE125) | AF127: =MAX(AF5:AF125) | AG127: =MAX(AG5:AG125) | ... AJ127: =MAX(AJ5:AJ125)
B128: =MIN(B5:B125) | C128: =MIN(C5:C125) | D128: =MIN(D5:D125) | E128: =MIN(E5:E125) | F128: =MIN(F5:F125) | G128: =MIN(G5:G125) | H128: =MIN(H5:H125) | I128: =MIN(I5:I125) | ... L128: =MIN(L5:L125) | N128: =MIN(N5:N125) | O128: =MIN(O5:O125) | P128: =MIN(P5:P125) | Q128: =MIN(Q5:Q125) | R128: =MIN(R5:R125) | S128: =MIN(S5:S125) | T128: =MIN(T5:T125) | U128: =MIN(U5:U125) | ... X128: =MIN(X5:X125) | Z128: =MIN(Z5:Z125) | AA128: =MIN(AA5:AA125) | AB128: =MIN(AB5:AB125) | AC128: =MIN(AC5:AC125) | AD128: =MIN(AD5:AD125) | AE128: =MIN(AE5:AE125) | AF128: =MIN(AF5:AF125) | AG128: =MIN(AG5:AG125) | ... AJ128: =MIN(AJ5:AJ125)
B129: =AVERAGE(B5:B125) | C129: =AVERAGE(C5:C125) | D129: =AVERAGE(D5:D125) | E129: =AVERAGE(E5:E125) | F129: =AVERAGE(F5:F125) | G129: =AVERAGE(G5:G125) | H129: =AVERAGE(H5:H125) | I129: =AVERAGE(I5:I125) | ... L129: =AVERAGE(L5:L125) | N129: =AVERAGE(N5:N125) | O129: =AVERAGE(O5:O125) | P129: =AVERAGE(P5:P125) | Q129: =AVERAGE(Q5:Q125) | R129: =AVERAGE(R5:R125) | S129: =AVERAGE(S5:S125) | T129: =AVERAGE(T5:T125) | U129: =AVERAGE(U5:U125) | ... X129: =AVERAGE(X5:X125) | Z129: =AVERAGE(Z5:Z125) | AA129: =AVERAGE(AA5:AA125) | AB129: =AVERAGE(AB5:AB125) | AC129: =AVERAGE(AC5:AC125) | AD129: =AVERAGE(AD5:AD125) | AE129: =AVERAGE(AE5:AE125) | AF129: =AVERAGE(AF5:AF125) | AG129: =AVERAGE(AG5:AG125) | ... AJ129: =AVERAGE(AJ5:AJ125)
B130: =B125 | C130: =C125 | D130: =D125 | E130: =E125 | F130: =F125 | G130: =G125 | H130: =H125 | I130: =I125 | ... L130: =L125 | N130: =N125 | O130: =O125 | P130: =P125 | Q130: =Q125 | R130: =R125 | S130: =S125 | T130: =T125 | U130: =U125 | ... X130: =X125 | Z130: =Z125 | AA130: =AA125 | AB130: =AB125 | AC130: =AC125 | AD130: =AD125 | AE130: =AE125 | AF130: =AF125 | AG130: =AG125 | ... AJ130: =AJ125
